Workbook

Sheet DASHBOARD

Sheet STUDY AREA 1
A2: STUDY AREA 1, BLOCK 1
R3: Power Factor | S3: kVA | U3: TRANSFORMER SIZE
A4: LOAD | B4: NO. OF ESTABLISHMENTS | C4: ESTIMATED AVERAGE AMPACITY | D4: NUMBER OF PHASE | E4: VOLTAGE | F4: POWER (kW) | H4: SIMULTANEOUS MAXIMUM DEMAND | I4: = | J4: =TRUNC(SUMIF(A4:A8,"Residential Load",F4:F8),3)&"(0.6)" -> 448.5(0.6) | K4: + | L4: =TRUNC(SUMIF(A4:A8,"Commercial Load",F4:F8),3)&"(0.7)" -> 179.4(0.7) | M4: + | N4: =TRUNC(SUMIF(A4:A8,"Industrial Load",F4:F8),3)&"(0.65)" -> 0(0.65) | O4: ="=" -> = | P4: =((SUMIF(A4:A8,"Residential Load",F4:F8)*MID(J4,LEN(J4)-3,3))/J5)+((SUMIF(A4:A8,"Commercial Load",F4:F8)*MID(L4,LEN(L4)-3,3))/L5)+((SUMIF(A4:A8,"Industrial Load",F4:F8)*MID(N4,LEN(N4)-3,3))/N5) -> 220.5637 | Q4: kW | R4: 0.9 | S4: =P4/R4 -> 245.07078 | U4: USE 1 - 300 kVA TRANSFORMER | Y4: =MID(U4,9,SEARCH("T",U4,1)-14)*1 -> 300
A5: Residential Load | B5: 130 | C5: 15 | D5: 1 | E5: 230 | F5: =Table1[[#This Row],[NO. OF ESTABLISHMENTS]]*Table1[[#This Row],[ESTIMATED AVERAGE AMPACITY]]*Table1[[#This Row],[VOLTAGE]]/1000 -> 448.5 | J5: 2 | L5: 1.46 | N5: 0.86 | AA5: LOAD
A6: Commercial Load | B6: 12 | C6: 65 | D6: 1 | E6: 230 | F6: =Table1[[#This Row],[NO. OF ESTABLISHMENTS]]*Table1[[#This Row],[ESTIMATED AVERAGE AMPACITY]]*Table1[[#This Row],[VOLTAGE]]/1000 -> 179.4 | AA6: Residential Load | AC6: =SUMIF($A$4:$F$145,AA6,$F$4:$F$145) -> 9142.5
A7: Industrial Load | B7: 0 | C7: 0 | D7: 0 | E7: 0 | F7: =Table1[[#This Row],[NO. OF ESTABLISHMENTS]]*Table1[[#This Row],[ESTIMATED AVERAGE AMPACITY]]*Table1[[#This Row],[VOLTAGE]]/1000 -> 0 | P7: =IF((COUNTIF(A4:A8,"Commercial Load (Bulk)")>0),(LOOKUP("Commercial Load (Bulk)",A4:A8,F4:F8)*MID(J7,LEN(J7)-3,3))/J8,IF(COUNTIF(A4:A8,"Industrial Load (Bulk)")>0,(LOOKUP("Industrial Load (Bulk)",A4:A8,F4:F8)*MID(J7,LEN(J7)-3,3))/J8,"")) | S7: =IF(ISBLANK(R7),"",P7/R7) | AA7: Commercial Load | AC7: =SUMIF($A$4:$F$145,AA7,$F$4:$F$145) -> 6814.9
AA8: Industrial Load | AC8: =SUMIF($A$4:$F$145,AA8,$F$4:$F$145) -> 0
A10: STUDY AREA 1, BLOCK 2
R11: Power Factor | S11: kVA
A12: LOAD | B12: NO. OF ESTABLISHMENTS | C12: ESTIMATED AVERAGE AMPACITY | D12: NUMBER OF PHASE | E12: VOLTAGE | F12: POWER (kW) | H12: SIMULTANEOUS MAXIMUM DEMAND | I12: = | J12: =TRUNC(SUMIF(A12:A16,"Residential Load",F12:F16),3)&"(0.6)" -> 552(0.6) | K12: + | L12: =TRUNC(SUMIF(A12:A16,"Commercial Load",F12:F16),3)&"(0.7)" -> 299(0.7) | M12: + | N12: =TRUNC(SUMIF(A12:A16,"Industrial Load",F12:F16),3)&"(0.65)" -> 0(0.65) | O12: ="=" -> = | P12: =((SUMIF(A12:A16,"Residential Load",F12:F16)*MID(J12,LEN(J12)-3,3))/J13)+((SUMIF(A12:A16,"Commercial Load",F12:F16)*MID(L12,LEN(L12)-3,3))/L13)+((SUMIF(A12:A16,"Industrial Load",F12:F16)*MID(N12,LEN(N12)-3,3))/N13) -> 308.95616 | Q12: kW | R12: 0.9 | S12: =P12/R12 -> 343.28463 | U12: USE 1 - 450 kVA TRANSFORMER | Y12: =MID(U12,9,SEARCH("T",U12,1)-14)*1 -> 450
A13: Residential Load | B13: 120 | C13: 20 | D13: 1 | E13: 230 | F13: =Table15[[#This Row],[NO. OF ESTABLISHMENTS]]*Table15[[#This Row],[ESTIMATED AVERAGE AMPACITY]]*Table15[[#This Row],[VOLTAGE]]/1000 -> 552 | J13: 2 | L13: 1.46 | N13: 0.86
A14: Commercial Load | B14: 20 | C14: 65 | D14: 1 | E14: 230 | F14: =Table15[[#This Row],[NO. OF ESTABLISHMENTS]]*Table15[[#This Row],[ESTIMATED AVERAGE AMPACITY]]*Table15[[#This Row],[VOLTAGE]]/1000 -> 299
A15: Industrial Load | B15: 0 | C15: 0 | D15: 0 | E15: 0 | F15: =Table15[[#This Row],[NO. OF ESTABLISHMENTS]]*Table15[[#This Row],[ESTIMATED AVERAGE AMPACITY]]*Table15[[#This Row],[VOLTAGE]]/1000 -> 0 | H15: SIMULTANEOUS MAXIMUM DEMAND (BULK) | I15: ="=" -> = | J15: =IF((COUNTIF(A12:A16,"Commercial Load (Bulk)")>0),TRUNC(LOOKUP("Commercial Load (Bulk)",A12:A16,F12:F16))&"(0.7)",IF(COUNTIF(A12:A16,"Industrial Load (Bulk)")>0,TRUNC(LOOKUP("Industrial Load (Bulk)",A12:A16,F12:F16))&"(0.7)","")) | P15: =IF((COUNTIF(A12:A16,"Commercial Load (Bulk)")>0),(LOOKUP("Commercial Load (Bulk)",A12:A16,F12:F16)*MID(J15,LEN(J15)-3,3))/J16,IF(COUNTIF(A12:A16,"Industrial Load (Bulk)")>0,(LOOKUP("Industrial Load (Bulk)",A12:A16,F12:F16)*MID(J15,LEN(J15)-3,3))/J16,"")) | S15: =IF(ISBLANK(R15),"",P15/R15)
J16: =IF((COUNTIF(A12:A16,"Commercial Load (Bulk)")>0),"0.9",IF(COUNTIF(A12:A16,"Industrial Load (Bulk)")>0,"0.9",""))
A18: STUDY AREA 1, BLOCK 3
R19: Power Factor | S19: kVA
A20: LOAD | B20: NO. OF ESTABLISHMENTS | C20: ESTIMATED AVERAGE AMPACITY | D20: NUMBER OF PHASE | E20: VOLTAGE | F20: POWER (kW) | H20: SIMULTANEOUS MAXIMUM DEMAND | I20: = | J20: =TRUNC(SUMIF(A20:A24,"Residential Load",F20:F24),3)&"(0.6)" -> 1472(0.6) | K20: + | L20: =TRUNC(SUMIF(A20:A24,"Commercial Load",F20:F24),3)&"(0.7)" -> 690(0.7) | M20: + | N20: =TRUNC(SUMIF(A20:A24,"Industrial Load",F20:F24),3)&"(0.65)" -> 0(0.65) | O20: ="=" -> = | P20: =((SUMIF(A20:A24,"Residential Load",F20:F24)*MID(J20,LEN(J20)-3,3))/J21)+((SUMIF(A20:A24,"Commercial Load",F20:F24)*MID(L20,LEN(L20)-3,3))/L21)+((SUMIF(A20:A24,"Industrial Load",F20:F24)*MID(N20,LEN(N20)-3,3))/N21) -> 772.42192 | Q20: kW | R20: 0.9 | S20: =P20/R20 -> 858.24658 | U20: USE 1 - 1000 kVA TRANSFORMER | Y20: =MID(U20,9,SEARCH("T",U20,1)-14)*1 -> 1000
A21: Residential Load | B21: 160 | C21: 40 | D21: 1 | E21: 230 | F21: =Table16[[#This Row],[NO. OF ESTABLISHMENTS]]*Table16[[#This Row],[ESTIMATED AVERAGE AMPACITY]]*Table16[[#This Row],[VOLTAGE]]/1000 -> 1472 | J21: 2 | L21: 1.46 | N21: 0.86
A22: Commercial Load | B22: 40 | C22: 75 | D22: 1 | E22: 230 | F22: =Table16[[#This Row],[NO. OF ESTABLISHMENTS]]*Table16[[#This Row],[ESTIMATED AVERAGE AMPACITY]]*Table16[[#This Row],[VOLTAGE]]/1000 -> 690
A23: Commercial Load (Bulk) | B23: 1 | C23: 3000 | D23: 3 | E23: 400 | F23: =SQRT(3)*Table16[[#This Row],[NO. OF ESTABLISHMENTS]]*Table16[[#This Row],[ESTIMATED AVERAGE AMPACITY]]*Table16[[#This Row],[VOLTAGE]]/1000 -> 2078.461 | H23: SIMULTANEOUS MAXIMUM DEMAND (BULK) | I23: ="=" -> = | J23: =IF((COUNTIF(A20:A24,"Commercial Load (Bulk)")>0),TRUNC(LOOKUP("Commercial Load (Bulk)",A20:A24,F20:F24))&"(0.7)",IF(COUNTIF(A20:A24,"Industrial Load (Bulk)")>0,TRUNC(LOOKUP("Industrial Load (Bulk)",A20:A24,F20:F24))&"(0.7)","")) -> 2078(0.7) | P23: =IF((COUNTIF(A20:A24,"Commercial Load (Bulk)")>0),(LOOKUP("Commercial Load (Bulk)",A20:A24,F20:F24)*MID(J23,LEN(J23)-3,3))/J24,IF(COUNTIF(A20:A24,"Industrial Load (Bulk)")>0,(LOOKUP("Industrial Load (Bulk)",A20:A24,F20:F24)*MID(J23,LEN(J23)-3,3))/J24,"")) -> 1616.5808 | Q23: kVA | S23: =IF(ISBLANK(R23),"",P23/R23) | U23: USE 1 - 2000 kVA TRANSFORMER | Y23: =MID(U23,9,SEARCH("T",U23,1)-14)*1 -> 2000
A24: Industrial Load | B24: 0 | C24: 0 | D24: 0 | E24: 0 | F24: =SQRT(3)*Table16[[#This Row],[NO. OF ESTABLISHMENTS]]*Table16[[#This Row],[ESTIMATED AVERAGE AMPACITY]]*Table16[[#This Row],[VOLTAGE]]/1000 -> 0 | J24: =IF((COUNTIF(A20:A24,"Commercial Load (Bulk)")>0),"0.9",IF(COUNTIF(A20:A24,"Industrial Load (Bulk)")>0,"0.9","")) -> 0.9
A27: STUDY AREA 1, BLOCK 4
R28: Power Factor | S28: kVA
A29: LOAD | B29: NO. OF ESTABLISHMENTS | C29: ESTIMATED AVERAGE AMPACITY | D29: NUMBER OF PHASE | E29: VOLTAGE | F29: POWER (kW) | H29: SIMULTANEOUS MAXIMUM DEMAND | I29: = | J29: =TRUNC(SUMIF(A29:A33,"Residential Load",F29:F33),3)&"(0.6)" -> 276(0.6) | K29: + | L29: =TRUNC(SUMIF(A29:A33,"Commercial Load",F29:F33),3)&"(0.7)" -> 241.5(0.7) | M29: + | N29: =TRUNC(SUMIF(A29:A33,"Industrial Load",F29:F33),3)&"(0.65)" -> 0(0.65) | O29: ="=" -> = | P29: =((SUMIF(A29:A33,"Residential Load",F29:F33)*MID(J29,LEN(J29)-3,3))/J30)+((SUMIF(A29:A33,"Commercial Load",F29:F33)*MID(L29,LEN(L29)-3,3))/L30)+((SUMIF(A29:A33,"Industrial Load",F29:F33)*MID(N29,LEN(N29)-3,3))/N30) -> 198.58767 | Q29: kW | R29: 0.9 | S29: =P29/R29 -> 220.65297 | U29: USE 1 - 225 kVA TRANSFORMER | Y29: =MID(U29,9,SEARCH("T",U29,1)-14)*1 -> 225
A30: Residential Load | B30: 80 | C30: 15 | D30: 1 | E30: 230 | F30: =Table17[[#This Row],[NO. OF ESTABLISHMENTS]]*Table17[[#This Row],[ESTIMATED AVERAGE AMPACITY]]*Table17[[#This Row],[VOLTAGE]]/1000 -> 276 | J30: 2 | L30: 1.46 | N30: 0.86
A31: Commercial Load | B31: 15 | C31: 70 | D31: 1 | E31: 230 | F31: =Table17[[#This Row],[NO. OF ESTABLISHMENTS]]*Table17[[#This Row],[ESTIMATED AVERAGE AMPACITY]]*Table17[[#This Row],[VOLTAGE]]/1000 -> 241.5
A32: Industrial Load | B32: 0 | C32: 0 | D32: 0 | E32: 0 | F32: =Table17[[#This Row],[NO. OF ESTABLISHMENTS]]*Table17[[#This Row],[ESTIMATED AVERAGE AMPACITY]]*Table17[[#This Row],[VOLTAGE]]/1000 -> 0 | H32: SIMULTANEOUS MAXIMUM DEMAND (BULK) | I32: ="=" -> = | J32: =IF((COUNTIF(A29:A33,"Commercial Load (Bulk)")>0),TRUNC(LOOKUP("Commercial Load (Bulk)",A29:A33,F29:F33))&"(0.7)",IF(COUNTIF(A29:A33,"Industrial Load (Bulk)")>0,TRUNC(LOOKUP("Industrial Load (Bulk)",A29:A33,F29:F33))&"(0.7)","")) | P32: =IF((COUNTIF(A29:A33,"Commercial Load (Bulk)")>0),(LOOKUP("Commercial Load (Bulk)",A29:A33,F29:F33)*MID(J32,LEN(J32)-3,3))/J33,IF(COUNTIF(A29:A33,"Industrial Load (Bulk)")>0,(LOOKUP("Industrial Load (Bulk)",A29:A33,F29:F33)*MID(J32,LEN(J32)-3,3))/J33,"")) | S32: =IF(ISBLANK(R32),"",P32/R32)
J33: =IF((COUNTIF(A29:A33,"Commercial Load (Bulk)")>0),"0.9",IF(COUNTIF(A29:A33,"Industrial Load (Bulk)")>0,"0.9",""))
A35: STUDY AREA 1, BLOCK 5
R36: Power Factor | S36: kVA
A37: LOAD | B37: NO. OF ESTABLISHMENTS | C37: ESTIMATED AVERAGE AMPACITY | D37: NUMBER OF PHASE | E37: VOLTAGE | F37: POWER (kW) | H37: SIMULTANEOUS MAXIMUM DEMAND | I37: = | J37: =TRUNC(SUMIF(A37:A41,"Residential Load",F37:F41),3)&"(0.6)" -> 276(0.6) | K37: + | L37: =TRUNC(SUMIF(A37:A41,"Commercial Load",F37:F41),3)&"(0.7)" -> 276(0.7) | M37: + | N37: =TRUNC(SUMIF(A37:A41,"Industrial Load",F37:F41),3)&"(0.65)" -> 0(0.65) | O37: ="=" -> = | P37: =((SUMIF(A37:A41,"Residential Load",F37:F41)*MID(J37,LEN(J37)-3,3))/J38)+((SUMIF(A37:A41,"Commercial Load",F37:F41)*MID(L37,LEN(L37)-3,3))/L38)+((SUMIF(A37:A41,"Industrial Load",F37:F41)*MID(N37,LEN(N37)-3,3))/N38) -> 215.12877 | Q37: kW | R37: 0.9 | S37: =P37/R37 -> 239.03196 | U37: USE 1 - 300 kVA TRANSFORMER | Y37: =MID(U37,9,SEARCH("T",U37,1)-14)*1 -> 300
A38: Residential Load | B38: 60 | C38: 20 | D38: 1 | E38: 230 | F38: =Table158[[#This Row],[NO. OF ESTABLISHMENTS]]*Table158[[#This Row],[ESTIMATED AVERAGE AMPACITY]]*Table158[[#This Row],[VOLTAGE]]/1000 -> 276 | J38: 2 | L38: 1.46 | N38: 0.86
A39: Commercial Load | B39: 15 | C39: 80 | D39: 1 | E39: 230 | F39: =Table158[[#This Row],[NO. OF ESTABLISHMENTS]]*Table158[[#This Row],[ESTIMATED AVERAGE AMPACITY]]*Table158[[#This Row],[VOLTAGE]]/1000 -> 276
A40: Industrial Load | B40: 0 | C40: 0 | D40: 0 | E40: 0 | F40: =Table158[[#This Row],[NO. OF ESTABLISHMENTS]]*Table158[[#This Row],[ESTIMATED AVERAGE AMPACITY]]*Table158[[#This Row],[VOLTAGE]]/1000 -> 0 | H40: SIMULTANEOUS MAXIMUM DEMAND (BULK) | I40: ="=" -> = | J40: =IF((COUNTIF(A37:A41,"Commercial Load (Bulk)")>0),TRUNC(LOOKUP("Commercial Load (Bulk)",A37:A41,F37:F41))&"(0.7)",IF(COUNTIF(A37:A41,"Industrial Load (Bulk)")>0,TRUNC(LOOKUP("Industrial Load (Bulk)",A37:A41,F37:F41))&"(0.7)","")) | P40: =IF((COUNTIF(A37:A41,"Commercial Load (Bulk)")>0),(LOOKUP("Commercial Load (Bulk)",A37:A41,F37:F41)*MID(J40,LEN(J40)-3,3))/J41,IF(COUNTIF(A37:A41,"Industrial Load (Bulk)")>0,(LOOKUP("Industrial Load (Bulk)",A37:A41,F37:F41)*MID(J40,LEN(J40)-3,3))/J41,"")) | S40: =IF(ISBLANK(R40),"",P40/R40)
J41: =IF((COUNTIF(A37:A41,"Commercial Load (Bulk)")>0),"0.9",IF(COUNTIF(A37:A41,"Industrial Load (Bulk)")>0,"0.9",""))
A43: STUDY AREA 1, BLOCK 6
R44: Power Factor | S44: kVA
A45: LOAD | B45: NO. OF ESTABLISHMENTS | C45: ESTIMATED AVERAGE AMPACITY | D45: NUMBER OF PHASE | E45: VOLTAGE | F45: POWER (kW) | H45: SIMULTANEOUS MAXIMUM DEMAND | I45: = | J45: =TRUNC(SUMIF(A45:A49,"Residential Load",F45:F49),3)&"(0.6)" -> 276(0.6) | K45: + | L45: =TRUNC(SUMIF(A45:A49,"Commercial Load",F45:F49),3)&"(0.7)" -> 414(0.7) | M45: + | N45: =TRUNC(SUMIF(A45:A49,"Industrial Load",F45:F49),3)&"(0.65)" -> 0(0.65) | O45: ="=" -> = | P45: =((SUMIF(A45:A49,"Residential Load",F45:F49)*MID(J45,LEN(J45)-3,3))/J46)+((SUMIF(A45:A49,"Commercial Load",F45:F49)*MID(L45,LEN(L45)-3,3))/L46)+((SUMIF(A45:A49,"Industrial Load",F45:F49)*MID(N45,LEN(N45)-3,3))/N46) -> 281.29315 | Q45: kW | R45: 0.9 | S45: =P45/R45 -> 312.54795 | U45: USE 1 - 450 kVA TRANSFORMER | Y45: =MID(U45,9,SEARCH("T",U45,1)-14)*1 -> 450
A46: Residential Load | B46: 40 | C46: 30 | D46: 1 | E46: 230 | F46: =Table169[[#This Row],[NO. OF ESTABLISHMENTS]]*Table169[[#This Row],[ESTIMATED AVERAGE AMPACITY]]*Table169[[#This Row],[VOLTAGE]]/1000 -> 276 | J46: 2 | L46: 1.46 | N46: 0.86
A47: Commercial Load | B47: 20 | C47: 90 | D47: 1 | E47: 230 | F47: =Table169[[#This Row],[NO. OF ESTABLISHMENTS]]*Table169[[#This Row],[ESTIMATED AVERAGE AMPACITY]]*Table169[[#This Row],[VOLTAGE]]/1000 -> 414
...

Sheet STUDY AREA 2
A2: STUDY AREA 2, BLOCK 1
R3: Power Factor | S3: kVA | U3: TRANSFORMER SIZE
A4: LOAD | B4: NO. OF ESTABLISHMENTS | C4: ESTIMATED AVERAGE AMPACITY | D4: NUMBER OF PHASE | E4: VOLTAGE | F4: POWER (kW) | H4: SIMULTANEOUS MAXIMUM DEMAND | I4: = | J4: =TRUNC(SUMIF(A4:A8,"Residential Load",F4:F8),3)&"(0.6)" -> 1242(0.6) | K4: + | L4: =TRUNC(SUMIF(A4:A8,"Commercial Load",F4:F8),3)&"(0.7)" -> 414(0.7) | M4: + | N4: =TRUNC(SUMIF(A4:A8,"Industrial Load",F4:F8),3)&"(0.65)" -> 0(0.65) | O4: ="=" -> = | P4: =((SUMIF(A4:A8,"Residential Load",F4:F8)*MID(J4,LEN(J4)-3,3))/J5)+((SUMIF(A4:A8,"Commercial Load",F4:F8)*MID(L4,LEN(L4)-3,3))/L5)+((SUMIF(A4:A8,"Industrial Load",F4:F8)*MID(N4,LEN(N4)-3,3))/N5) -> 571.09315 | Q4: kW | R4: 0.9 | S4: =P4/R4 -> 634.54795 | U4: USE 1 - 800 kVA TRANSFORMER | Y4: =MID(U4,9,SEARCH("T",U4,1)-14)*1 -> 800
A5: Residential Load | B5: 120 | C5: 45 | D5: 1 | E5: 230 | F5: =Table122[[#This Row],[NO. OF ESTABLISHMENTS]]*Table122[[#This Row],[ESTIMATED AVERAGE AMPACITY]]*Table122[[#This Row],[VOLTAGE]]/1000 -> 1242 | J5: 2 | L5: 1.46 | N5: 0.86 | AA5: LOAD
A6: Commercial Load | B6: 20 | C6: 90 | D6: 1 | E6: 230 | F6: =Table122[[#This Row],[NO. OF ESTABLISHMENTS]]*Table122[[#This Row],[ESTIMATED AVERAGE AMPACITY]]*Table122[[#This Row],[VOLTAGE]]/1000 -> 414 | AA6: Residential Load | AC6: =SUMIF($A$4:$F$119,AA6,$F$4:$F$119) -> 10683.5
A7: Industrial Load | B7: 0 | C7: 0 | D7: 0 | E7: 0 | F7: 0 | H7: SIMULTANEOUS MAXIMUM DEMAND (BULK) | I7: ="=" -> = | J7: =IF((COUNTIF(A4:A8,"Commercial Load (Bulk)")>0),TRUNC(LOOKUP("Commercial Load (Bulk)",A4:A8,F4:F8))&"(0.7)",IF(COUNTIF(A4:A8,"Industrial Load (Bulk)")>0,TRUNC(LOOKUP("Industrial Load (Bulk)",A4:A8,F4:F8))&"(0.7)","")) | P7: =IF((COUNTIF(A4:A8,"Commercial Load (Bulk)")>0),(LOOKUP("Commercial Load (Bulk)",A4:A8,F4:F8)*MID(J7,LEN(J7)-3,3))/J8,IF(COUNTIF(A4:A8,"Industrial Load (Bulk)")>0,(LOOKUP("Industrial Load (Bulk)",A4:A8,F4:F8)*MID(J7,LEN(J7)-3,3))/J8,"")) | S7: =IF(ISBLANK(R7),"",P7/R7) | AA7: Commercial Load | AC7: =SUMIF($A$4:$F$119,AA7,$F$4:$F$119) -> 3869.75
J8: =IF((COUNTIF(A4:A8,"Commercial Load (Bulk)")>0),"0.9",IF(COUNTIF(A4:A8,"Industrial Load (Bulk)")>0,"0.9","")) | AA8: Industrial Load | AC8: =SUMIF($A$4:$F$119,AA8,$F$4:$F$119) -> 0
A10: STUDY AREA 2, BLOCK 2
R11: Power Factor | S11: kVA
A12: LOAD | B12: NO. OF ESTABLISHMENTS | C12: ESTIMATED AVERAGE AMPACITY | D12: NUMBER OF PHASE | E12: VOLTAGE | F12: POWER (kW) | H12: SIMULTANEOUS MAXIMUM DEMAND | I12: = | J12: =TRUNC(SUMIF(A12:A16,"Residential Load",F12:F16),3)&"(0.6)" -> 862.5(0.6) | K12: + | L12: =TRUNC(SUMIF(A12:A16,"Commercial Load",F12:F16),3)&"(0.7)" -> 258.75(0.7) | M12: + | N12: =TRUNC(SUMIF(A12:A16,"Industrial Load",F12:F16),3)&"(0.65)" -> 0(0.65) | O12: ="=" -> = | P12: =((SUMIF(A12:A16,"Residential Load",F12:F16)*MID(J12,LEN(J12)-3,3))/J13)+((SUMIF(A12:A16,"Commercial Load",F12:F16)*MID(L12,LEN(L12)-3,3))/L13)+((SUMIF(A12:A16,"Industrial Load",F12:F16)*MID(N12,LEN(N12)-3,3))/N13) -> 382.80822 | Q12: kW | R12: 0.9 | S12: =P12/R12 -> 425.34247 | U12: USE 1 - 450 kVA TRANSFORMER | Y12: =MID(U12,9,SEARCH("T",U12,1)-14)*1 -> 450
A13: Residential Load | B13: 150 | C13: 25 | D13: 1 | E13: 230 | F13: =Table1523[[#This Row],[NO. OF ESTABLISHMENTS]]*Table1523[[#This Row],[ESTIMATED AVERAGE AMPACITY]]*Table1523[[#This Row],[VOLTAGE]]/1000 -> 862.5 | J13: 2 | L13: 1.46 | N13: 0.86
A14: Commercial Load | B14: 15 | C14: 75 | D14: 1 | E14: 230 | F14: =Table1523[[#This Row],[NO. OF ESTABLISHMENTS]]*Table1523[[#This Row],[ESTIMATED AVERAGE AMPACITY]]*Table1523[[#This Row],[VOLTAGE]]/1000 -> 258.75
A15: Industrial Load | B15: 0 | C15: 0 | D15: 0 | E15: 0 | F15: 0 | H15: SIMULTANEOUS MAXIMUM DEMAND (BULK) | I15: ="=" -> = | J15: =IF((COUNTIF(A12:A16,"Commercial Load (Bulk)")>0),TRUNC(LOOKUP("Commercial Load (Bulk)",A12:A16,F12:F16))&"(0.7)",IF(COUNTIF(A12:A16,"Industrial Load (Bulk)")>0,TRUNC(LOOKUP("Industrial Load (Bulk)",A12:A16,F12:F16))&"(0.7)","")) | P15: =IF((COUNTIF(A12:A16,"Commercial Load (Bulk)")>0),(LOOKUP("Commercial Load (Bulk)",A12:A16,F12:F16)*MID(J15,LEN(J15)-3,3))/J16,IF(COUNTIF(A12:A16,"Industrial Load (Bulk)")>0,(LOOKUP("Industrial Load (Bulk)",A12:A16,F12:F16)*MID(J15,LEN(J15)-3,3))/J16,"")) | S15: =IF(ISBLANK(R15),"",P15/R15)
J16: =IF((COUNTIF(A12:A16,"Commercial Load (Bulk)")>0),"0.9",IF(COUNTIF(A12:A16,"Industrial Load (Bulk)")>0,"0.9",""))
A18: STUDY AREA 2, BLOCK 3
R19: Power Factor | S19: kVA
A20: LOAD | B20: NO. OF ESTABLISHMENTS | C20: ESTIMATED AVERAGE AMPACITY | D20: NUMBER OF PHASE | E20: VOLTAGE | F20: POWER (kW) | H20: SIMULTANEOUS MAXIMUM DEMAND | I20: = | J20: =TRUNC(SUMIF(A20:A24,"Residential Load",F20:F24),3)&"(0.6)" -> 172.5(0.6) | K20: + | L20: =TRUNC(SUMIF(A20:A24,"Commercial Load",F20:F24),3)&"(0.7)" -> 74.75(0.7) | M20: + | N20: =TRUNC(SUMIF(A20:A24,"Industrial Load",F20:F24),3)&"(0.65)" -> 0(0.65) | O20: ="=" -> = | P20: =((SUMIF(A20:A24,"Residential Load",F20:F24)*MID(J20,LEN(J20)-3,3))/J21)+((SUMIF(A20:A24,"Commercial Load",F20:F24)*MID(L20,LEN(L20)-3,3))/L21)+((SUMIF(A20:A24,"Industrial Load",F20:F24)*MID(N20,LEN(N20)-3,3))/N21) -> 87.589041 | Q20: kW | R20: 0.9 | S20: =P20/R20 -> 97.321157 | U20: USE 1 - 112.5 kVA TRANSFORMER | Y20: =MID(U20,9,SEARCH("T",U20,1)-14)*1 -> 112.5
A21: Residential Load | B21: 50 | C21: 15 | D21: 1 | E21: 230 | F21: =Table1624[[#This Row],[NO. OF ESTABLISHMENTS]]*Table1624[[#This Row],[ESTIMATED AVERAGE AMPACITY]]*Table1624[[#This Row],[VOLTAGE]]/1000 -> 172.5 | J21: 2 | L21: 1.46 | N21: 0.86
A22: Commercial Load | B22: 5 | C22: 65 | D22: 1 | E22: 230 | F22: =Table1624[[#This Row],[NO. OF ESTABLISHMENTS]]*Table1624[[#This Row],[ESTIMATED AVERAGE AMPACITY]]*Table1624[[#This Row],[VOLTAGE]]/1000 -> 74.75
A23: Industrial Load (Bulk) | B23: 1 | C23: 1500 | D23: 3 | E23: 1000 | F23: =Table1624[[#This Row],[NO. OF ESTABLISHMENTS]]*Table1624[[#This Row],[ESTIMATED AVERAGE AMPACITY]]*Table1624[[#This Row],[VOLTAGE]]*SQRT(3)/1000 -> 2598.0762 | H23: SIMULTANEOUS MAXIMUM DEMAND (BULK) | I23: ="=" -> = | J23: =IF((COUNTIF(A20:A24,"Commercial Load (Bulk)")>0),TRUNC(LOOKUP("Commercial Load (Bulk)",A20:A24,F20:F24))&"(0.7)",IF(COUNTIF(A20:A24,"Industrial Load (Bulk)")>0,TRUNC(LOOKUP("Industrial Load (Bulk)",A20:A24,F20:F24))&"(0.7)","")) -> 2598(0.7) | P23: =IF((COUNTIF(A20:A24,"Commercial Load (Bulk)")>0),(LOOKUP("Commercial Load (Bulk)",A20:A24,F20:F24)*MID(J23,LEN(J23)-3,3))/J24,IF(COUNTIF(A20:A24,"Industrial Load (Bulk)")>0,(LOOKUP("Industrial Load (Bulk)",A20:A24,F20:F24)*MID(J23,LEN(J23)-3,3))/J24,"")) -> 2020.7259 | Q23: kVA | S23: =IF(ISBLANK(R23),"",P23/R23) | U23: USE 1 - 2500 kVA TRANSFORMER | Y23: =MID(U23,9,SEARCH("T",U23,1)-14)*1 -> 2500
J24: =IF((COUNTIF(A20:A24,"Commercial Load (Bulk)")>0),"0.9",IF(COUNTIF(A20:A24,"Industrial Load (Bulk)")>0,"0.9","")) -> 0.9
A26: STUDY AREA 2, BLOCK 4
R27: Power Factor | S27: kVA
A28: LOAD | B28: NO. OF ESTABLISHMENTS | C28: ESTIMATED AVERAGE AMPACITY | D28: NUMBER OF PHASE | E28: VOLTAGE | F28: POWER (kW) | H28: SIMULTANEOUS MAXIMUM DEMAND | I28: = | J28: =TRUNC(SUMIF(A28:A32,"Residential Load",F28:F32),3)&"(0.6)" -> 230(0.6) | K28: + | L28: =TRUNC(SUMIF(A28:A32,"Commercial Load",F28:F32),3)&"(0.7)" -> 74.75(0.7) | M28: + | N28: =TRUNC(SUMIF(A28:A32,"Industrial Load",F28:F32),3)&"(0.65)" -> 0(0.65) | O28: ="=" -> = | P28: =((SUMIF(A28:A32,"Residential Load",F28:F32)*MID(J28,LEN(J28)-3,3))/J29)+((SUMIF(A28:A32,"Commercial Load",F28:F32)*MID(L28,LEN(L28)-3,3))/L29)+((SUMIF(A28:A32,"Industrial Load",F28:F32)*MID(N28,LEN(N28)-3,3))/N29) -> 104.83904 | Q28: kW | R28: 0.9 | S28: =P28/R28 -> 116.48782 | U28: USE 1 - 150 kVA TRANSFORMER | Y28: =MID(U28,9,SEARCH("T",U28,1)-14)*1 -> 150
A29: Residential Load | B29: 50 | C29: 20 | D29: 1 | E29: 230 | F29: =Table1725[[#This Row],[NO. OF ESTABLISHMENTS]]*Table1725[[#This Row],[ESTIMATED AVERAGE AMPACITY]]*Table1725[[#This Row],[VOLTAGE]]/1000 -> 230 | J29: 2 | L29: 1.46 | N29: 0.86
A30: Commercial Load | B30: 5 | C30: 65 | D30: 1 | E30: 230 | F30: =Table1725[[#This Row],[NO. OF ESTABLISHMENTS]]*Table1725[[#This Row],[ESTIMATED AVERAGE AMPACITY]]*Table1725[[#This Row],[VOLTAGE]]/1000 -> 74.75
A31: Industrial Load | B31: 0 | C31: 0 | D31: 0 | E31: 0 | F31: 0 | H31: SIMULTANEOUS MAXIMUM DEMAND (BULK) | I31: ="=" -> = | J31: =IF((COUNTIF(A28:A32,"Commercial Load (Bulk)")>0),TRUNC(LOOKUP("Commercial Load (Bulk)",A28:A32,F28:F32))&"(0.7)",IF(COUNTIF(A28:A32,"Industrial Load (Bulk)")>0,TRUNC(LOOKUP("Industrial Load (Bulk)",A28:A32,F28:F32))&"(0.7)","")) | P31: =IF((COUNTIF(A28:A32,"Commercial Load (Bulk)")>0),(LOOKUP("Commercial Load (Bulk)",A28:A32,F28:F32)*MID(J31,LEN(J31)-3,3))/J32,IF(COUNTIF(A28:A32,"Industrial Load (Bulk)")>0,(LOOKUP("Industrial Load (Bulk)",A28:A32,F28:F32)*MID(J31,LEN(J31)-3,3))/J32,"")) | S31: =IF(ISBLANK(R31),"",P31/R31)
J32: =IF((COUNTIF(A28:A32,"Commercial Load (Bulk)")>0),"0.9",IF(COUNTIF(A28:A32,"Industrial Load (Bulk)")>0,"0.9",""))
A34: STUDY AREA 2, BLOCK 5
R35: Power Factor | S35: kVA
A36: LOAD | B36: NO. OF ESTABLISHMENTS | C36: ESTIMATED AVERAGE AMPACITY | D36: NUMBER OF PHASE | E36: VOLTAGE | F36: POWER (kW) | H36: SIMULTANEOUS MAXIMUM DEMAND | I36: = | J36: =TRUNC(SUMIF(A36:A40,"Residential Load",F36:F40),3)&"(0.6)" -> 172.5(0.6) | K36: + | L36: =TRUNC(SUMIF(A36:A40,"Commercial Load",F36:F40),3)&"(0.7)" -> 74.75(0.7) | M36: + | N36: =TRUNC(SUMIF(A36:A40,"Industrial Load",F36:F40),3)&"(0.65)" -> 0(0.65) | O36: ="=" -> = | P36: =((SUMIF(A36:A40,"Residential Load",F36:F40)*MID(J36,LEN(J36)-3,3))/J37)+((SUMIF(A36:A40,"Commercial Load",F36:F40)*MID(L36,LEN(L36)-3,3))/L37)+((SUMIF(A36:A40,"Industrial Load",F36:F40)*MID(N36,LEN(N36)-3,3))/N37) -> 87.589041 | Q36: kW | R36: 0.9 | S36: =P36/R36 -> 97.321157 | U36: USE 1 - 112.5 kVA TRANSFORMER | Y36: =MID(U36,9,SEARCH("T",U36,1)-14)*1 -> 112.5
A37: Residential Load | B37: 50 | C37: 15 | D37: 1 | E37: 230 | F37: =Table15826[[#This Row],[NO. OF ESTABLISHMENTS]]*Table15826[[#This Row],[ESTIMATED AVERAGE AMPACITY]]*Table15826[[#This Row],[VOLTAGE]]/1000 -> 172.5 | J37: 2 | L37: 1.46 | N37: 0.86
A38: Commercial Load | B38: 5 | C38: 65 | D38: 1 | E38: 230 | F38: =Table15826[[#This Row],[NO. OF ESTABLISHMENTS]]*Table15826[[#This Row],[ESTIMATED AVERAGE AMPACITY]]*Table15826[[#This Row],[VOLTAGE]]/1000 -> 74.75
A39: Industrial Load | B39: 0 | C39: 0 | D39: 0 | E39: 0 | F39: 0 | H39: SIMULTANEOUS MAXIMUM DEMAND (BULK) | I39: ="=" -> = | J39: =IF((COUNTIF(A36:A40,"Commercial Load (Bulk)")>0),TRUNC(LOOKUP("Commercial Load (Bulk)",A36:A40,F36:F40))&"(0.7)",IF(COUNTIF(A36:A40,"Industrial Load (Bulk)")>0,TRUNC(LOOKUP("Industrial Load (Bulk)",A36:A40,F36:F40))&"(0.7)","")) | P39: =IF((COUNTIF(A36:A40,"Commercial Load (Bulk)")>0),(LOOKUP("Commercial Load (Bulk)",A36:A40,F36:F40)*MID(J39,LEN(J39)-3,3))/J40,IF(COUNTIF(A36:A40,"Industrial Load (Bulk)")>0,(LOOKUP("Industrial Load (Bulk)",A36:A40,F36:F40)*MID(J39,LEN(J39)-3,3))/J40,"")) | S39: =IF(ISBLANK(R39),"",P39/R39)
J40: =IF((COUNTIF(A36:A40,"Commercial Load (Bulk)")>0),"0.9",IF(COUNTIF(A36:A40,"Industrial Load (Bulk)")>0,"0.9",""))
A42: STUDY AREA 2, BLOCK 6
R43: Power Factor | S43: kVA
A44: LOAD | B44: NO. OF ESTABLISHMENTS | C44: ESTIMATED AVERAGE AMPACITY | D44: NUMBER OF PHASE | E44: VOLTAGE | F44: POWER (kW) | H44: SIMULTANEOUS MAXIMUM DEMAND | I44: = | J44: =TRUNC(SUMIF(A44:A48,"Residential Load",F44:F48),3)&"(0.6)" -> 920(0.6) | K44: + | L44: =TRUNC(SUMIF(A44:A48,"Commercial Load",F44:F48),3)&"(0.7)" -> 546.25(0.7) | M44: + | N44: =TRUNC(SUMIF(A44:A48,"Industrial Load",F44:F48),3)&"(0.65)" -> 0(0.65) | O44: ="=" -> = | P44: =((SUMIF(A44:A48,"Residential Load",F44:F48)*MID(J44,LEN(J44)-3,3))/J45)+((SUMIF(A44:A48,"Commercial Load",F44:F48)*MID(L44,LEN(L44)-3,3))/L45)+((SUMIF(A44:A48,"Industrial Load",F44:F48)*MID(N44,LEN(N44)-3,3))/N45) -> 537.90068 | Q44: kW | R44: 0.9 | S44: =P44/R44 -> 597.66743 | U44: USE 1 - 600 kVA TRANSFORMER | Y44: =MID(U44,9,SEARCH("T",U44,1)-14)*1 -> 600
A45: Residential Load | B45: 100 | C45: 40 | D45: 1 | E45: 230 | F45: =Table16927[[#This Row],[NO. OF ESTABLISHMENTS]]*Table16927[[#This Row],[ESTIMATED AVERAGE AMPACITY]]*Table16927[[#This Row],[VOLTAGE]]/1000 -> 920 | J45: 2 | L45: 1.46 | N45: 0.86
A46: Commercial Load | B46: 25 | C46: 95 | D46: 1 | E46: 230 | F46: =Table16927[[#This Row],[NO. OF ESTABLISHMENTS]]*Table16927[[#This Row],[ESTIMATED AVERAGE AMPACITY]]*Table16927[[#This Row],[VOLTAGE]]/1000 -> 546.25
...

Sheet STUDY AREA 3
A2: STUDY AREA 3, BLOCK 1
R3: Power Factor | S3: kVA | U3: TRANSFORMER SIZE
A4: LOAD | B4: NO. OF ESTABLISHMENTS | C4: ESTIMATED AVERAGE AMPACITY | D4: NUMBER OF PHASE | E4: VOLTAGE | F4: POWER (kW) | H4: SIMULTANEOUS MAXIMUM DEMAND | I4: = | J4: =TRUNC(SUMIF(A4:A8,"Residential Load",F4:F8),3)&"(0.6)" -> 736(0.6) | K4: + | L4: =TRUNC(SUMIF(A4:A8,"Commercial Load",F4:F8),3)&"(0.7)" -> 80.5(0.7) | M4: + | N4: =TRUNC(SUMIF(A4:A8,"Industrial Load",F4:F8),3)&"(0.65)" -> 0(0.65) | O4: ="=" -> = | P4: =((SUMIF(A4:A8,"Residential Load",F4:F8)*MID(J4,LEN(J4)-3,3))/J5)+((SUMIF(A4:A8,"Commercial Load",F4:F8)*MID(L4,LEN(L4)-3,3))/L5)+((SUMIF(A4:A8,"Industrial Load",F4:F8)*MID(N4,LEN(N4)-3,3))/N5) -> 259.39589 | Q4: kW | R4: 0.9 | S4: =P4/R4 -> 288.21766 | U4: USE 1 - 300 kVA TRANSFORMER | Y4: =MID(U4,9,SEARCH("T",U4,1)-14)*1 -> 300
A5: Residential Load | B5: 160 | C5: 20 | D5: 1 | E5: 230 | F5: =Table122110[[#This Row],[NO. OF ESTABLISHMENTS]]*Table122110[[#This Row],[ESTIMATED AVERAGE AMPACITY]]*Table122110[[#This Row],[VOLTAGE]]/1000 -> 736 | J5: 2 | L5: 1.46 | N5: 0.86 | AA5: LOAD
A6: Commercial Load | B6: 5 | C6: 70 | D6: 1 | E6: 230 | F6: =Table122110[[#This Row],[NO. OF ESTABLISHMENTS]]*Table122110[[#This Row],[ESTIMATED AVERAGE AMPACITY]]*Table122110[[#This Row],[VOLTAGE]]/1000 -> 80.5 | AA6: Residential Load | AC6: =SUMIF($A$4:$F$121,AA6,$F$4:$F$121) -> 7820
A7: Industrial Load | B7: 0 | C7: 0 | D7: 0 | E7: 0 | F7: 0 | H7: SIMULTANEOUS MAXIMUM DEMAND (BULK) | I7: ="=" -> = | J7: =IF((COUNTIF(A4:A8,"Commercial Load (Bulk)")>0),TRUNC(LOOKUP("Commercial Load (Bulk)",A4:A8,F4:F8))&"(0.7)",IF(COUNTIF(A4:A8,"Industrial Load (Bulk)")>0,TRUNC(LOOKUP("Industrial Load (Bulk)",A4:A8,F4:F8))&"(0.7)","")) | P7: =IF((COUNTIF(A4:A8,"Commercial Load (Bulk)")>0),(LOOKUP("Commercial Load (Bulk)",A4:A8,F4:F8)*MID(J7,LEN(J7)-3,3))/J8,IF(COUNTIF(A4:A8,"Industrial Load (Bulk)")>0,(LOOKUP("Industrial Load (Bulk)",A4:A8,F4:F8)*MID(J7,LEN(J7)-3,3))/J8,"")) | S7: =IF(ISBLANK(R7),"",P7/R7) | AA7: Commercial Load | AC7: =SUMIF($A$4:$F$121,AA7,$F$4:$F$121) -> 3070.5
J8: =IF((COUNTIF(A4:A8,"Commercial Load (Bulk)")>0),"0.9",IF(COUNTIF(A4:A8,"Industrial Load (Bulk)")>0,"0.9","")) | AA8: Industrial Load | AC8: =SUMIF($A$4:$F$121,AA8,$F$4:$F$121) -> 0
A10: STUDY AREA 3, BLOCK 2
R11: Power Factor | S11: kVA
A12: LOAD | B12: NO. OF ESTABLISHMENTS | C12: ESTIMATED AVERAGE AMPACITY | D12: NUMBER OF PHASE | E12: VOLTAGE | F12: POWER (kW) | H12: SIMULTANEOUS MAXIMUM DEMAND | I12: = | J12: =TRUNC(SUMIF(A12:A16,"Residential Load",F12:F16),3)&"(0.6)" -> 805(0.6) | K12: + | L12: =TRUNC(SUMIF(A12:A16,"Commercial Load",F12:F16),3)&"(0.7)" -> 172.5(0.7) | M12: + | N12: =TRUNC(SUMIF(A12:A16,"Industrial Load",F12:F16),3)&"(0.65)" -> 0(0.65) | O12: ="=" -> = | P12: =((SUMIF(A12:A16,"Residential Load",F12:F16)*MID(J12,LEN(J12)-3,3))/J13)+((SUMIF(A12:A16,"Commercial Load",F12:F16)*MID(L12,LEN(L12)-3,3))/L13)+((SUMIF(A12:A16,"Industrial Load",F12:F16)*MID(N12,LEN(N12)-3,3))/N13) -> 324.20548 | Q12: kW | R12: 0.9 | S12: =P12/R12 -> 360.22831 | U12: USE 1 - 450 kVA TRANSFORMER | Y12: =MID(U12,9,SEARCH("T",U12,1)-14)*1 -> 450
A13: Residential Load | B13: 140 | C13: 25 | D13: 1 | E13: 230 | F13: =Table1523111[[#This Row],[NO. OF ESTABLISHMENTS]]*Table1523111[[#This Row],[ESTIMATED AVERAGE AMPACITY]]*Table1523111[[#This Row],[VOLTAGE]]/1000 -> 805 | J13: 2 | L13: 1.46 | N13: 0.86
A14: Commercial Load | B14: 10 | C14: 75 | D14: 1 | E14: 230 | F14: =Table1523111[[#This Row],[NO. OF ESTABLISHMENTS]]*Table1523111[[#This Row],[ESTIMATED AVERAGE AMPACITY]]*Table1523111[[#This Row],[VOLTAGE]]/1000 -> 172.5
A15: Industrial Load | B15: 0 | C15: 0 | D15: 0 | E15: 0 | F15: 0 | H15: SIMULTANEOUS MAXIMUM DEMAND (BULK) | I15: ="=" -> = | J15: =IF((COUNTIF(A12:A16,"Commercial Load (Bulk)")>0),TRUNC(LOOKUP("Commercial Load (Bulk)",A12:A16,F12:F16))&"(0.7)",IF(COUNTIF(A12:A16,"Industrial Load (Bulk)")>0,TRUNC(LOOKUP("Industrial Load (Bulk)",A12:A16,F12:F16))&"(0.7)","")) | P15: =IF((COUNTIF(A12:A16,"Commercial Load (Bulk)")>0),(LOOKUP("Commercial Load (Bulk)",A12:A16,F12:F16)*MID(J15,LEN(J15)-3,3))/J16,IF(COUNTIF(A12:A16,"Industrial Load (Bulk)")>0,(LOOKUP("Industrial Load (Bulk)",A12:A16,F12:F16)*MID(J15,LEN(J15)-3,3))/J16,"")) | S15: =IF(ISBLANK(R15),"",P15/R15)
J16: =IF((COUNTIF(A12:A16,"Commercial Load (Bulk)")>0),"0.9",IF(COUNTIF(A12:A16,"Industrial Load (Bulk)")>0,"0.9",""))
A18: STUDY AREA 3, BLOCK 3
R19: Power Factor | S19: kVA
A20: LOAD | B20: NO. OF ESTABLISHMENTS | C20: ESTIMATED AVERAGE AMPACITY | D20: NUMBER OF PHASE | E20: VOLTAGE | F20: POWER (kW) | H20: SIMULTANEOUS MAXIMUM DEMAND | I20: = | J20: =TRUNC(SUMIF(A20:A24,"Residential Load",F20:F24),3)&"(0.6)" -> 575(0.6) | K20: + | L20: =TRUNC(SUMIF(A20:A24,"Commercial Load",F20:F24),3)&"(0.7)" -> 368(0.7) | M20: + | N20: =TRUNC(SUMIF(A20:A24,"Industrial Load",F20:F24),3)&"(0.65)" -> 0(0.65) | O20: ="=" -> = | P20: =((SUMIF(A20:A24,"Residential Load",F20:F24)*MID(J20,LEN(J20)-3,3))/J21)+((SUMIF(A20:A24,"Commercial Load",F20:F24)*MID(L20,LEN(L20)-3,3))/L21)+((SUMIF(A20:A24,"Industrial Load",F20:F24)*MID(N20,LEN(N20)-3,3))/N21) -> 348.93836 | Q20: kW | R20: 0.9 | S20: =P20/R20 -> 387.70928 | U20: USE 1 - 450 kVA TRANSFORMER | Y20: =MID(U20,9,SEARCH("T",U20,1)-14)*1 -> 450
A21: Residential Load | B21: 100 | C21: 25 | D21: 1 | E21: 230 | F21: =Table1624112[[#This Row],[NO. OF ESTABLISHMENTS]]*Table1624112[[#This Row],[ESTIMATED AVERAGE AMPACITY]]*Table1624112[[#This Row],[VOLTAGE]]/1000 -> 575 | J21: 2 | L21: 1.46 | N21: 0.86
A22: Commercial Load | B22: 20 | C22: 80 | D22: 1 | E22: 230 | F22: =Table1624112[[#This Row],[NO. OF ESTABLISHMENTS]]*Table1624112[[#This Row],[ESTIMATED AVERAGE AMPACITY]]*Table1624112[[#This Row],[VOLTAGE]]/1000 -> 368
A23: Industrial Load | B23: 0 | C23: 0 | D23: 0 | E23: 0 | F23: 0 | H23: SIMULTANEOUS MAXIMUM DEMAND (BULK) | I23: ="=" -> = | J23: =IF((COUNTIF(A20:A24,"Commercial Load (Bulk)")>0),TRUNC(LOOKUP("Commercial Load (Bulk)",A20:A24,F20:F24))&"(0.7)",IF(COUNTIF(A20:A24,"Industrial Load (Bulk)")>0,TRUNC(LOOKUP("Industrial Load (Bulk)",A20:A24,F20:F24))&"(0.7)","")) | P23: =IF((COUNTIF(A20:A24,"Commercial Load (Bulk)")>0),(LOOKUP("Commercial Load (Bulk)",A20:A24,F20:F24)*MID(J23,LEN(J23)-3,3))/J24,IF(COUNTIF(A20:A24,"Industrial Load (Bulk)")>0,(LOOKUP("Industrial Load (Bulk)",A20:A24,F20:F24)*MID(J23,LEN(J23)-3,3))/J24,"")) | S23: =IF(ISBLANK(R23),"",P23/R23)
J24: =IF((COUNTIF(A20:A24,"Commercial Load (Bulk)")>0),"0.9",IF(COUNTIF(A20:A24,"Industrial Load (Bulk)")>0,"0.9",""))
A26: STUDY AREA 3, BLOCK 4
R27: Power Factor | S27: kVA
A28: LOAD | B28: NO. OF ESTABLISHMENTS | C28: ESTIMATED AVERAGE AMPACITY | D28: NUMBER OF PHASE | E28: VOLTAGE | F28: POWER (kW) | H28: SIMULTANEOUS MAXIMUM DEMAND | I28: = | J28: =TRUNC(SUMIF(A28:A32,"Residential Load",F28:F32),3)&"(0.6)" -> 241.5(0.6) | K28: + | L28: =TRUNC(SUMIF(A28:A32,"Commercial Load",F28:F32),3)&"(0.7)" -> 149.5(0.7) | M28: + | N28: =TRUNC(SUMIF(A28:A32,"Industrial Load",F28:F32),3)&"(0.65)" -> 0(0.65) | O28: ="=" -> = | P28: =((SUMIF(A28:A32,"Residential Load",F28:F32)*MID(J28,LEN(J28)-3,3))/J29)+((SUMIF(A28:A32,"Commercial Load",F28:F32)*MID(L28,LEN(L28)-3,3))/L29)+((SUMIF(A28:A32,"Industrial Load",F28:F32)*MID(N28,LEN(N28)-3,3))/N29) -> 144.12808 | Q28: kW | R28: 0.9 | S28: =P28/R28 -> 160.14231 | U28: USE 1 - 225 kVA TRANSFORMER | Y28: =MID(U28,9,SEARCH("T",U28,1)-14)*1 -> 225
A29: Residential Load | B29: 70 | C29: 15 | D29: 1 | E29: 230 | F29: =Table1725113[[#This Row],[NO. OF ESTABLISHMENTS]]*Table1725113[[#This Row],[ESTIMATED AVERAGE AMPACITY]]*Table1725113[[#This Row],[VOLTAGE]]/1000 -> 241.5 | J29: 2 | L29: 1.46 | N29: 0.86
A30: Commercial Load | B30: 10 | C30: 65 | D30: 1 | E30: 230 | F30: =Table1725113[[#This Row],[NO. OF ESTABLISHMENTS]]*Table1725113[[#This Row],[ESTIMATED AVERAGE AMPACITY]]*Table1725113[[#This Row],[VOLTAGE]]/1000 -> 149.5
A31: Industrial Load | B31: 0 | C31: 0 | D31: 0 | E31: 0 | F31: 0 | H31: SIMULTANEOUS MAXIMUM DEMAND (BULK) | I31: ="=" -> = | J31: =IF((COUNTIF(A28:A32,"Commercial Load (Bulk)")>0),TRUNC(LOOKUP("Commercial Load (Bulk)",A28:A32,F28:F32))&"(0.7)",IF(COUNTIF(A28:A32,"Industrial Load (Bulk)")>0,TRUNC(LOOKUP("Industrial Load (Bulk)",A28:A32,F28:F32))&"(0.7)","")) | P31: =IF((COUNTIF(A28:A32,"Commercial Load (Bulk)")>0),(LOOKUP("Commercial Load (Bulk)",A28:A32,F28:F32)*MID(J31,LEN(J31)-3,3))/J32,IF(COUNTIF(A28:A32,"Industrial Load (Bulk)")>0,(LOOKUP("Industrial Load (Bulk)",A28:A32,F28:F32)*MID(J31,LEN(J31)-3,3))/J32,"")) | S31: =IF(ISBLANK(R31),"",P31/R31)
J32: =IF((COUNTIF(A28:A32,"Commercial Load (Bulk)")>0),"0.9",IF(COUNTIF(A28:A32,"Industrial Load (Bulk)")>0,"0.9",""))
A34: STUDY AREA 3, BLOCK 5
R35: Power Factor | S35: kVA
A36: LOAD | B36: NO. OF ESTABLISHMENTS | C36: ESTIMATED AVERAGE AMPACITY | D36: NUMBER OF PHASE | E36: VOLTAGE | F36: POWER (kW) | H36: SIMULTANEOUS MAXIMUM DEMAND | I36: = | J36: =TRUNC(SUMIF(A36:A40,"Residential Load",F36:F40),3)&"(0.6)" -> 460(0.6) | K36: + | L36: =TRUNC(SUMIF(A36:A40,"Commercial Load",F36:F40),3)&"(0.7)" -> 74.75(0.7) | M36: + | N36: =TRUNC(SUMIF(A36:A40,"Industrial Load",F36:F40),3)&"(0.65)" -> 0(0.65) | O36: ="=" -> = | P36: =((SUMIF(A36:A40,"Residential Load",F36:F40)*MID(J36,LEN(J36)-3,3))/J37)+((SUMIF(A36:A40,"Commercial Load",F36:F40)*MID(L36,LEN(L36)-3,3))/L37)+((SUMIF(A36:A40,"Industrial Load",F36:F40)*MID(N36,LEN(N36)-3,3))/N37) -> 173.83904 | Q36: kW | R36: 0.9 | S36: =P36/R36 -> 193.15449 | U36: USE 1 - 225 kVA TRANSFORMER | Y36: =MID(U36,9,SEARCH("T",U36,1)-14)*1 -> 225
A37: Residential Load | B37: 80 | C37: 25 | D37: 1 | E37: 230 | F37: =Table15826114[[#This Row],[NO. OF ESTABLISHMENTS]]*Table15826114[[#This Row],[ESTIMATED AVERAGE AMPACITY]]*Table15826114[[#This Row],[VOLTAGE]]/1000 -> 460 | J37: 2 | L37: 1.46 | N37: 0.86
A38: Commercial Load | B38: 5 | C38: 65 | D38: 1 | E38: 230 | F38: =Table15826114[[#This Row],[NO. OF ESTABLISHMENTS]]*Table15826114[[#This Row],[ESTIMATED AVERAGE AMPACITY]]*Table15826114[[#This Row],[VOLTAGE]]/1000 -> 74.75
A39: Industrial Load | B39: 0 | C39: 0 | D39: 0 | E39: 0 | F39: 0 | H39: SIMULTANEOUS MAXIMUM DEMAND (BULK) | I39: ="=" -> = | J39: =IF((COUNTIF(A36:A40,"Commercial Load (Bulk)")>0),TRUNC(LOOKUP("Commercial Load (Bulk)",A36:A40,F36:F40))&"(0.7)",IF(COUNTIF(A36:A40,"Industrial Load (Bulk)")>0,TRUNC(LOOKUP("Industrial Load (Bulk)",A36:A40,F36:F40))&"(0.7)","")) | P39: =IF((COUNTIF(A36:A40,"Commercial Load (Bulk)")>0),(LOOKUP("Commercial Load (Bulk)",A36:A40,F36:F40)*MID(J39,LEN(J39)-3,3))/J40,IF(COUNTIF(A36:A40,"Industrial Load (Bulk)")>0,(LOOKUP("Industrial Load (Bulk)",A36:A40,F36:F40)*MID(J39,LEN(J39)-3,3))/J40,"")) | S39: =IF(ISBLANK(R39),"",P39/R39)
J40: =IF((COUNTIF(A36:A40,"Commercial Load (Bulk)")>0),"0.9",IF(COUNTIF(A36:A40,"Industrial Load (Bulk)")>0,"0.9",""))
A42: STUDY AREA 3, BLOCK 6
R43: Power Factor | S43: kVA
A44: LOAD | B44: NO. OF ESTABLISHMENTS | C44: ESTIMATED AVERAGE AMPACITY | D44: NUMBER OF PHASE | E44: VOLTAGE | F44: POWER (kW) | H44: SIMULTANEOUS MAXIMUM DEMAND | I44: = | J44: =TRUNC(SUMIF(A44:A48,"Residential Load",F44:F48),3)&"(0.6)" -> 483(0.6) | K44: + | L44: =TRUNC(SUMIF(A44:A48,"Commercial Load",F44:F48),3)&"(0.7)" -> 258.75(0.7) | M44: + | N44: =TRUNC(SUMIF(A44:A48,"Industrial Load",F44:F48),3)&"(0.65)" -> 0(0.65) | O44: ="=" -> = | P44: =((SUMIF(A44:A48,"Residential Load",F44:F48)*MID(J44,LEN(J44)-3,3))/J45)+((SUMIF(A44:A48,"Commercial Load",F44:F48)*MID(L44,LEN(L44)-3,3))/L45)+((SUMIF(A44:A48,"Industrial Load",F44:F48)*MID(N44,LEN(N44)-3,3))/N45) -> 268.95822 | Q44: kW | R44: 0.9 | S44: =P44/R44 -> 298.84247 | U44: USE 1 - 300 kVA TRANSFORMER | Y44: =MID(U44,9,SEARCH("T",U44,1)-14)*1 -> 300
A45: Residential Load | B45: 70 | C45: 30 | D45: 1 | E45: 230 | F45: =Table16927115[[#This Row],[NO. OF ESTABLISHMENTS]]*Table16927115[[#This Row],[ESTIMATED AVERAGE AMPACITY]]*Table16927115[[#This Row],[VOLTAGE]]/1000 -> 483 | J45: 2 | L45: 1.46 | N45: 0.86
A46: Commercial Load | B46: 15 | C46: 75 | D46: 1 | E46: 230 | F46: =Table16927115[[#This Row],[NO. OF ESTABLISHMENTS]]*Table16927115[[#This Row],[ESTIMATED AVERAGE AMPACITY]]*Table16927115[[#This Row],[VOLTAGE]]/1000 -> 258.75
...

Sheet STUDY AREA 4
A2: STUDY AREA 4, BLOCK 1
R3: Power Factor | S3: kVA | U3: TRANSFORMER SIZE
A4: LOAD | B4: NO. OF ESTABLISHMENTS | C4: ESTIMATED AVERAGE AMPACITY | D4: NUMBER OF PHASE | E4: VOLTAGE | F4: POWER (kW) | H4: SIMULTANEOUS MAXIMUM DEMAND | I4: = | J4: =TRUNC(SUMIF(A4:A8,"Residential Load",F4:F8),3)&"(0.6)" -> 460(0.6) | K4: + | L4: =TRUNC(SUMIF(A4:A8,"Commercial Load",F4:F8),3)&"(0.7)" -> 517.5(0.7) | M4: + | N4: =TRUNC(SUMIF(A4:A8,"Industrial Load",F4:F8),3)&"(0.65)" -> 0(0.65) | O4: ="=" -> = | P4: =((SUMIF(A4:A8,"Residential Load",F4:F8)*MID(J4,LEN(J4)-3,3))/J5)+((SUMIF(A4:A8,"Commercial Load",F4:F8)*MID(L4,LEN(L4)-3,3))/L5)+((SUMIF(A4:A8,"Industrial Load",F4:F8)*MID(N4,LEN(N4)-3,3))/N5) -> 386.11644 | Q4: kW | R4: 0.9 | S4: =P4/R4 -> 429.01826 | U4: USE 1 - 450 kVA TRANSFORMER | Y4: =MID(U4,9,SEARCH("T",U4,1)-14)*1 -> 450
A5: Residential Load | B5: 50 | C5: 40 | D5: 1 | E5: 230 | F5: =Table122110128[[#This Row],[NO. OF ESTABLISHMENTS]]*Table122110128[[#This Row],[ESTIMATED AVERAGE AMPACITY]]*Table122110128[[#This Row],[VOLTAGE]]/1000 -> 460 | J5: 2 | L5: 1.46 | N5: 0.86 | AA5: LOAD
A6: Commercial Load | B6: 25 | C6: 90 | D6: 1 | E6: 230 | F6: =Table122110128[[#This Row],[NO. OF ESTABLISHMENTS]]*Table122110128[[#This Row],[ESTIMATED AVERAGE AMPACITY]]*Table122110128[[#This Row],[VOLTAGE]]/1000 -> 517.5 | AA6: Residential Load | AC6: =SUMIF($A$4:$F$129,AA6,$F$4:$F$129) -> 8619.25
A7: Commercial Load (Bulk) | B7: 1 | C7: 4000 | D7: 3 | E7: 400 | F7: =SQRT(3)*Table122110128[[#This Row],[NO. OF ESTABLISHMENTS]]*Table122110128[[#This Row],[ESTIMATED AVERAGE AMPACITY]]*Table122110128[[#This Row],[VOLTAGE]]/1000 -> 2771.2813 | H7: SIMULTANEOUS MAXIMUM DEMAND (BULK) | I7: ="=" -> = | J7: =IF((COUNTIF(A4:A8,"Commercial Load (Bulk)")>0),TRUNC(LOOKUP("Commercial Load (Bulk)",A4:A8,F4:F8))&"(0.7)",IF(COUNTIF(A4:A8,"Industrial Load (Bulk)")>0,TRUNC(LOOKUP("Industrial Load (Bulk)",A4:A8,F4:F8))&"(0.7)","")) -> 2771(0.7) | P7: =IF((COUNTIF(A4:A8,"Commercial Load (Bulk)")>0),(LOOKUP("Commercial Load (Bulk)",A4:A8,F4:F8)*MID(J7,LEN(J7)-3,3))/J8,IF(COUNTIF(A4:A8,"Industrial Load (Bulk)")>0,(LOOKUP("Industrial Load (Bulk)",A4:A8,F4:F8)*MID(J7,LEN(J7)-3,3))/J8,"")) -> 2155.441 | Q7: kVA | S7: =IF(ISBLANK(R7),"",P7/R7) | U7: USE 1 - 2500 kVA TRANSFORMER | Y7: =MID(U7,9,SEARCH("T",U7,1)-14)*1 -> 2500 | AA7: Commercial Load | AC7: =SUMIF($A$4:$F$129,AA7,$F$4:$F$129) -> 4433.25
A8: Industrial Load | B8: 0 | C8: 0 | D8: 0 | E8: 0 | F8: 0 | J8: =IF((COUNTIF(A4:A8,"Commercial Load (Bulk)")>0),"0.9",IF(COUNTIF(A4:A8,"Industrial Load (Bulk)")>0,"0.9","")) -> 0.9 | AA8: Industrial Load | AC8: =SUMIF($A$4:$F$129,AA8,$F$4:$F$129) -> 0
A11: STUDY AREA 4, BLOCK 2
R12: Power Factor | S12: kVA
A13: LOAD | B13: NO. OF ESTABLISHMENTS | C13: ESTIMATED AVERAGE AMPACITY | D13: NUMBER OF PHASE | E13: VOLTAGE | F13: POWER (kW) | H13: SIMULTANEOUS MAXIMUM DEMAND | I13: = | J13: =TRUNC(SUMIF(A12:A16,"Residential Load",F12:F16),3)&"(0.6)" -> 603.75(0.6) | K13: + | L13: =TRUNC(SUMIF(A12:A16,"Commercial Load",F12:F16),3)&"(0.7)" -> 368(0.7) | M13: + | N13: =TRUNC(SUMIF(A12:A16,"Industrial Load",F12:F16),3)&"(0.65)" -> 0(0.65) | O13: ="=" -> = | P13: =((SUMIF(A12:A16,"Residential Load",F12:F16)*MID(J13,LEN(J13)-3,3))/J14)+((SUMIF(A12:A16,"Commercial Load",F12:F16)*MID(L13,LEN(L13)-3,3))/L14)+((SUMIF(A12:A16,"Industrial Load",F12:F16)*MID(N13,LEN(N13)-3,3))/N14) -> 357.56336 | Q13: kW | R13: 0.9 | S13: =P13/R13 -> 397.29262 | U13: USE 1 - 450 kVA TRANSFORMER | Y13: =MID(U13,9,SEARCH("T",U13,1)-14)*1 -> 450
A14: Residential Load | B14: 75 | C14: 35 | D14: 1 | E14: 230 | F14: =Table1523111129[[#This Row],[NO. OF ESTABLISHMENTS]]*Table1523111129[[#This Row],[ESTIMATED AVERAGE AMPACITY]]*Table1523111129[[#This Row],[VOLTAGE]]/1000 -> 603.75 | J14: 2 | L14: 1.46 | N14: 0.86
A15: Commercial Load | B15: 20 | C15: 80 | D15: 1 | E15: 230 | F15: =Table1523111129[[#This Row],[NO. OF ESTABLISHMENTS]]*Table1523111129[[#This Row],[ESTIMATED AVERAGE AMPACITY]]*Table1523111129[[#This Row],[VOLTAGE]]/1000 -> 368
A16: Industrial Load | B16: 0 | C16: 0 | D16: 0 | E16: 0 | F16: 0 | H16: SIMULTANEOUS MAXIMUM DEMAND (BULK) | I16: ="=" -> = | J16: =IF((COUNTIF(A13:A17,"Commercial Load (Bulk)")>0),TRUNC(LOOKUP("Commercial Load (Bulk)",A13:A17,F13:F17))&"(0.7)",IF(COUNTIF(A13:A17,"Industrial Load (Bulk)")>0,TRUNC(LOOKUP("Industrial Load (Bulk)",A13:A17,F13:F17))&"(0.7)","")) | P16: =IF((COUNTIF(A13:A17,"Commercial Load (Bulk)")>0),(LOOKUP("Commercial Load (Bulk)",A13:A17,F13:F17)*MID(J16,LEN(J16)-3,3))/J17,IF(COUNTIF(A13:A17,"Industrial Load (Bulk)")>0,(LOOKUP("Industrial Load (Bulk)",A13:A17,F13:F17)*MID(J16,LEN(J16)-3,3))/J17,"")) | S16: =IF(ISBLANK(R16),"",P16/R16)
J17: =IF((COUNTIF(A13:A17,"Commercial Load (Bulk)")>0),"0.9",IF(COUNTIF(A13:A17,"Industrial Load (Bulk)")>0,"0.9",""))
A19: STUDY AREA 4, BLOCK 3
R20: Power Factor | S20: kVA
A21: LOAD | B21: NO. OF ESTABLISHMENTS | C21: ESTIMATED AVERAGE AMPACITY | D21: NUMBER OF PHASE | E21: VOLTAGE | F21: POWER (kW) | H21: SIMULTANEOUS MAXIMUM DEMAND | I21: = | J21: =TRUNC(SUMIF(A20:A24,"Residential Load",F20:F24),3)&"(0.6)" -> 966(0.6) | K21: + | L21: =TRUNC(SUMIF(A20:A24,"Commercial Load",F20:F24),3)&"(0.7)" -> 431.25(0.7) | M21: + | N21: =TRUNC(SUMIF(A20:A24,"Industrial Load",F20:F24),3)&"(0.65)" -> 0(0.65) | O21: ="=" -> = | P21: =((SUMIF(A20:A24,"Residential Load",F20:F24)*MID(J21,LEN(J21)-3,3))/J22)+((SUMIF(A20:A24,"Commercial Load",F20:F24)*MID(L21,LEN(L21)-3,3))/L22)+((SUMIF(A20:A24,"Industrial Load",F20:F24)*MID(N21,LEN(N21)-3,3))/N22) -> 496.5637 | Q21: kW | R21: 0.9 | S21: =P21/R21 -> 551.73744 | U21: USE 1 - 600 kVA TRANSFORMER | Y21: =MID(U21,9,SEARCH("T",U21,1)-14)*1 -> 600
A22: Residential Load | B22: 140 | C22: 30 | D22: 1 | E22: 230 | F22: =Table1624112130[[#This Row],[NO. OF ESTABLISHMENTS]]*Table1624112130[[#This Row],[ESTIMATED AVERAGE AMPACITY]]*Table1624112130[[#This Row],[VOLTAGE]]/1000 -> 966 | J22: 2 | L22: 1.46 | N22: 0.86
A23: Commercial Load | B23: 25 | C23: 75 | D23: 1 | E23: 230 | F23: =Table1624112130[[#This Row],[NO. OF ESTABLISHMENTS]]*Table1624112130[[#This Row],[ESTIMATED AVERAGE AMPACITY]]*Table1624112130[[#This Row],[VOLTAGE]]/1000 -> 431.25
A24: Industrial Load | B24: 0 | C24: 0 | D24: 0 | E24: 0 | F24: 0 | H24: SIMULTANEOUS MAXIMUM DEMAND (BULK) | I24: ="=" -> = | J24: =IF((COUNTIF(A21:A25,"Commercial Load (Bulk)")>0),TRUNC(LOOKUP("Commercial Load (Bulk)",A21:A25,F21:F25))&"(0.7)",IF(COUNTIF(A21:A25,"Industrial Load (Bulk)")>0,TRUNC(LOOKUP("Industrial Load (Bulk)",A21:A25,F21:F25))&"(0.7)","")) | P24: =IF((COUNTIF(A21:A25,"Commercial Load (Bulk)")>0),(LOOKUP("Commercial Load (Bulk)",A21:A25,F21:F25)*MID(J24,LEN(J24)-3,3))/J25,IF(COUNTIF(A21:A25,"Industrial Load (Bulk)")>0,(LOOKUP("Industrial Load (Bulk)",A21:A25,F21:F25)*MID(J24,LEN(J24)-3,3))/J25,"")) | S24: =IF(ISBLANK(R24),"",P24/R24)
J25: =IF((COUNTIF(A21:A25,"Commercial Load (Bulk)")>0),"0.9",IF(COUNTIF(A21:A25,"Industrial Load (Bulk)")>0,"0.9",""))
A27: STUDY AREA 4, BLOCK 4
R28: Power Factor | S28: kVA
A29: LOAD | B29: NO. OF ESTABLISHMENTS | C29: ESTIMATED AVERAGE AMPACITY | D29: NUMBER OF PHASE | E29: VOLTAGE | F29: POWER (kW) | H29: SIMULTANEOUS MAXIMUM DEMAND | I29: = | J29: =TRUNC(SUMIF(A29:A33,"Residential Load",F29:F33),3)&"(0.6)" -> 402.5(0.6) | K29: + | L29: =TRUNC(SUMIF(A29:A33,"Commercial Load",F29:F33),3)&"(0.7)" -> 149.5(0.7) | M29: + | N29: =TRUNC(SUMIF(A29:A33,"Industrial Load",F29:F33),3)&"(0.65)" -> 0(0.65) | O29: ="=" -> = | P29: =((SUMIF(A29:A33,"Residential Load",F29:F33)*MID(J29,LEN(J29)-3,3))/J30)+((SUMIF(A29:A33,"Commercial Load",F29:F33)*MID(L29,LEN(L29)-3,3))/L30)+((SUMIF(A29:A33,"Industrial Load",F29:F33)*MID(N29,LEN(N29)-3,3))/N30) -> 192.42808 | Q29: kW | R29: 0.9 | S29: =P29/R29 -> 213.80898 | U29: USE 1 - 225 kVA TRANSFORMER | Y29: =MID(U29,9,SEARCH("T",U29,1)-14)*1 -> 225
A30: Residential Load | B30: 70 | C30: 25 | D30: 1 | E30: 230 | F30: =Table1725113131[[#This Row],[NO. OF ESTABLISHMENTS]]*Table1725113131[[#This Row],[ESTIMATED AVERAGE AMPACITY]]*Table1725113131[[#This Row],[VOLTAGE]]/1000 -> 402.5 | J30: 2 | L30: 1.46 | N30: 0.86
A31: Commercial Load | B31: 10 | C31: 65 | D31: 1 | E31: 230 | F31: =Table1725113131[[#This Row],[NO. OF ESTABLISHMENTS]]*Table1725113131[[#This Row],[ESTIMATED AVERAGE AMPACITY]]*Table1725113131[[#This Row],[VOLTAGE]]/1000 -> 149.5
A32: Industrial Load | B32: 0 | C32: 0 | D32: 0 | E32: 0 | F32: 0 | H32: SIMULTANEOUS MAXIMUM DEMAND (BULK) | I32: ="=" -> = | J32: =IF((COUNTIF(A29:A33,"Commercial Load (Bulk)")>0),TRUNC(LOOKUP("Commercial Load (Bulk)",A29:A33,F29:F33))&"(0.7)",IF(COUNTIF(A29:A33,"Industrial Load (Bulk)")>0,TRUNC(LOOKUP("Industrial Load (Bulk)",A29:A33,F29:F33))&"(0.7)","")) | P32: =IF((COUNTIF(A29:A33,"Commercial Load (Bulk)")>0),(LOOKUP("Commercial Load (Bulk)",A29:A33,F29:F33)*MID(J32,LEN(J32)-3,3))/J33,IF(COUNTIF(A29:A33,"Industrial Load (Bulk)")>0,(LOOKUP("Industrial Load (Bulk)",A29:A33,F29:F33)*MID(J32,LEN(J32)-3,3))/J33,"")) | S32: =IF(ISBLANK(R32),"",P32/R32)
J33: =IF((COUNTIF(A29:A33,"Commercial Load (Bulk)")>0),"0.9",IF(COUNTIF(A29:A33,"Industrial Load (Bulk)")>0,"0.9",""))
A35: STUDY AREA 4, BLOCK 5
R36: Power Factor | S36: kVA
A37: LOAD | B37: NO. OF ESTABLISHMENTS | C37: ESTIMATED AVERAGE AMPACITY | D37: NUMBER OF PHASE | E37: VOLTAGE | F37: POWER (kW) | H37: SIMULTANEOUS MAXIMUM DEMAND | I37: = | J37: =TRUNC(SUMIF(A37:A41,"Residential Load",F37:F41),3)&"(0.6)" -> 86.25(0.6) | K37: + | L37: =TRUNC(SUMIF(A37:A41,"Commercial Load",F37:F41),3)&"(0.7)" -> 74.75(0.7) | M37: + | N37: =TRUNC(SUMIF(A37:A41,"Industrial Load",F37:F41),3)&"(0.65)" -> 0(0.65) | O37: ="=" -> = | P37: =((SUMIF(A37:A41,"Residential Load",F37:F41)*MID(J37,LEN(J37)-3,3))/J38)+((SUMIF(A37:A41,"Commercial Load",F37:F41)*MID(L37,LEN(L37)-3,3))/L38)+((SUMIF(A37:A41,"Industrial Load",F37:F41)*MID(N37,LEN(N37)-3,3))/N38) -> 61.714041 | Q37: kW | R37: 0.9 | S37: =P37/R37 -> 68.571157 | U37: USE 1 - 75 kVA TRANSFORMER | Y37: =MID(U37,9,SEARCH("T",U37,1)-14)*1 -> 75
A38: Residential Load | B38: 25 | C38: 15 | D38: 1 | E38: 230 | F38: =Table15826114132[[#This Row],[NO. OF ESTABLISHMENTS]]*Table15826114132[[#This Row],[ESTIMATED AVERAGE AMPACITY]]*Table15826114132[[#This Row],[VOLTAGE]]/1000 -> 86.25 | J38: 2 | L38: 1.46 | N38: 0.86
A39: Commercial Load | B39: 5 | C39: 65 | D39: 1 | E39: 230 | F39: =Table15826114132[[#This Row],[NO. OF ESTABLISHMENTS]]*Table15826114132[[#This Row],[ESTIMATED AVERAGE AMPACITY]]*Table15826114132[[#This Row],[VOLTAGE]]/1000 -> 74.75
A40: Industrial Load | B40: 0 | C40: 0 | D40: 0 | E40: 0 | F40: 0 | H40: SIMULTANEOUS MAXIMUM DEMAND (BULK) | I40: ="=" -> = | J40: =IF((COUNTIF(A37:A41,"Commercial Load (Bulk)")>0),TRUNC(LOOKUP("Commercial Load (Bulk)",A37:A41,F37:F41))&"(0.7)",IF(COUNTIF(A37:A41,"Industrial Load (Bulk)")>0,TRUNC(LOOKUP("Industrial Load (Bulk)",A37:A41,F37:F41))&"(0.7)","")) | P40: =IF((COUNTIF(A37:A41,"Commercial Load (Bulk)")>0),(LOOKUP("Commercial Load (Bulk)",A37:A41,F37:F41)*MID(J40,LEN(J40)-3,3))/J41,IF(COUNTIF(A37:A41,"Industrial Load (Bulk)")>0,(LOOKUP("Industrial Load (Bulk)",A37:A41,F37:F41)*MID(J40,LEN(J40)-3,3))/J41,"")) | S40: =IF(ISBLANK(R40),"",P40/R40)
J41: =IF((COUNTIF(A37:A41,"Commercial Load (Bulk)")>0),"0.9",IF(COUNTIF(A37:A41,"Industrial Load (Bulk)")>0,"0.9",""))
A43: STUDY AREA 4, BLOCK 6
R44: Power Factor | S44: kVA
A45: LOAD | B45: NO. OF ESTABLISHMENTS | C45: ESTIMATED AVERAGE AMPACITY | D45: NUMBER OF PHASE | E45: VOLTAGE | F45: POWER (kW) | H45: SIMULTANEOUS MAXIMUM DEMAND | I45: = | J45: =TRUNC(SUMIF(A45:A49,"Residential Load",F45:F49),3)&"(0.6)" -> 86.25(0.6) | K45: + | L45: =TRUNC(SUMIF(A45:A49,"Commercial Load",F45:F49),3)&"(0.7)" -> 74.75(0.7) | M45: + | N45: =TRUNC(SUMIF(A45:A49,"Industrial Load",F45:F49),3)&"(0.65)" -> 0(0.65) | O45: ="=" -> = | P45: =((SUMIF(A45:A49,"Residential Load",F45:F49)*MID(J45,LEN(J45)-3,3))/J46)+((SUMIF(A45:A49,"Commercial Load",F45:F49)*MID(L45,LEN(L45)-3,3))/L46)+((SUMIF(A45:A49,"Industrial Load",F45:F49)*MID(N45,LEN(N45)-3,3))/N46) -> 61.714041 | Q45: kW | R45: 0.9 | S45: =P45/R45 -> 68.571157 | U45: USE 1 - 75 kVA TRANSFORMER | Y45: =MID(U45,9,SEARCH("T",U45,1)-14)*1 -> 75
A46: Residential Load | B46: 25 | C46: 15 | D46: 1 | E46: 230 | F46: =Table16927115133[[#This Row],[NO. OF ESTABLISHMENTS]]*Table16927115133[[#This Row],[ESTIMATED AVERAGE AMPACITY]]*Table16927115133[[#This Row],[VOLTAGE]]/1000 -> 86.25 | J46: 2 | L46: 1.46 | N46: 0.86
A47: Commercial Load | B47: 5 | C47: 65 | D47: 1 | E47: 230 | F47: =Table16927115133[[#This Row],[NO. OF ESTABLISHMENTS]]*Table16927115133[[#This Row],[ESTIMATED AVERAGE AMPACITY]]*Table16927115133[[#This Row],[VOLTAGE]]/1000 -> 74.75
...

Sheet FEEDER AND SUBSTATION
T1: Time | U1: Residential Load | V1: Commercial Load | W1: Industrial Load | X1: Combined | AA1: residential | AD1: commercial | AJ1: Month | AK1: Residential (MWh) | AL1: Commercial (MWh) | AM1: Industrial (MWh) | AN1: Combined (MWh)
A2: FEEDERS | B2: LOAD SIZE | C2: UNIT | F2: FEEDER | G2: BULK USER | H2: LOAD SIZE | I2: UNIT | K2: SUBSTATION SIZE | L2: UNIT | N2: POWER PLANT SIZE | O2: UNIT | Q2: LOAD | T2: 0 | U2: =($R$3/$AA$28)*AA2 -> 13431.574 | V2: =($R$4/$AD$28)*AD2 -> 3505.9416 | W2: 3879.794 | X2: =SUM(U2:W2) -> 20817.31 | Z2: 0 | AA2: 10 | AC2: 0 | AD2: 5 | AG2: LOAD | AH2: Power (kW) | AJ2: January | AK2: 21825.55 | AL2: 7260.23 | AM2: 2885.79 | AN2: 32875
A3: 1 | B3: =SUMIF('STUDY AREA 1'!H:H,"SIMULTANEOUS MAXIMUM DEMAND",'STUDY AREA 1'!S:S)/1.3 -> 5136.8956 | C3: kVA | F3: 1 | G3: 11 | H3: ='STUDY AREA 1'!P23 -> 1616.5808 | I3: kVA | K3: =SUM(Table2[LOAD SIZE])/1.2 -> 13960.143 | L3: kVA | N3: =SUM(K:K,H:H)/1.1 -> 27093.304 | O3: kVA | Q3: Residential Load | R3: =SUM('STUDY AREA 1'!AC6,'STUDY AREA 2'!AC6,'STUDY AREA 3'!AC6,'STUDY AREA 4'!AC6) -> 36265.25 | T3: 0.041666667 | U3: =($R$3/$AA$28)*AA3 -> 12088.417 | V3: =($R$4/$AD$28)*AD3 -> 2804.7533 | W3: 3879.794 | X3: =SUM(U3:W3) -> 18772.964 | Z3: 0.041666667 | AA3: 9 | AC3: 0.041666667 | AD3: 4 | AG3: Residential Load | AH3: 36265.25 | AJ3: February | AK3: 19713.4 | AL3: 6557.78 | AM3: 2606.52 | AN3: 29694
A4: 2 | B4: =SUMIF('STUDY AREA 2'!H:H,"SIMULTANEOUS MAXIMUM DEMAND",'STUDY AREA 2'!S:S)/1.3 -> 4325.1364 | C4: kVA | F4: 1 | G4: 12 | H4: ='STUDY AREA 1'!P64 -> 1562.6947 | I4: kVA | K4: Substation Transformer Size | Q4: Commercial Load | R4: =SUM('STUDY AREA 1'!AC7,'STUDY AREA 2'!AC7,'STUDY AREA 3'!AC7,'STUDY AREA 4'!AC7,H3:H4,H7:H10) -> 30151.098 | T4: 0.083333333 | U4: =($R$3/$AA$28)*AA4 -> 10745.259 | V4: =($R$4/$AD$28)*AD4 -> 2804.7533 | W4: 3879.794 | X4: =SUM(U4:W4) -> 17429.807 | Z4: 0.083333333 | AA4: 8 | AC4: 0.083333333 | AD4: 4 | AG4: Commercial Load | AH4: 30151.098 | AJ4: March | AK4: 21825.55 | AL4: 7260.23 | AM4: 2885.79 | AN4: 32875
A5: 3 | B5: =SUMIF('STUDY AREA 3'!H:H,"SIMULTANEOUS MAXIMUM DEMAND",'STUDY AREA 3'!S:S)/1.3 -> 3263.3825 | C5: kVA | F5: 2 | G5: 21 | H5: ='STUDY AREA 2'!P23 -> 2020.7259 | I5: kVA | Q5: Industrial Load | R5: =SUM('STUDY AREA 1'!AC8,'STUDY AREA 2'!AC8,'STUDY AREA 3'!AC8,'STUDY AREA 4'!AC8,H5:H6) -> 3879.7938 | T5: 0.125 | U5: =($R$3/$AA$28)*AA5 -> 10745.259 | V5: =($R$4/$AD$28)*AD5 -> 2103.5649 | W5: 3879.794 | X5: =SUM(U5:W5) -> 16728.618 | Z5: 0.125 | AA5: 8 | AC5: 0.125 | AD5: 3 | AG5: Industrial Load | AH5: 3879.7938 | AJ5: April | AK5: 21121.4 | AL5: 7026 | AM5: 2792.7 | AN5: 31814
A6: 4 | B6: =SUMIF('STUDY AREA 4'!H:H,"SIMULTANEOUS MAXIMUM DEMAND",'STUDY AREA 4'!S:S)/1.3 -> 4026.7571 | C6: kVA | F6: 2 | G6: 22 | H6: ='STUDY AREA 2'!P111 -> 1859.0679 | I6: kVA | T6: 0.16666667 | U6: =($R$3/$AA$28)*AA6 -> 12088.417 | V6: =($R$4/$AD$28)*AD6 -> 2103.5649 | W6: 3879.794 | X6: =SUM(U6:W6) -> 18071.776 | Z6: 0.16666667 | AA6: 9 | AC6: 0.16666667 | AD6: 3 | AJ6: May | AK6: 21825.55 | AL6: 7260.23 | AM6: 2885.79 | AN6: 32875
F7: 3 | G7: 31 | H7: ='STUDY AREA 3'!P71 -> 2155.441 | I7: kVA | T7: 0.20833333 | U7: =($R$3/$AA$28)*AA7 -> 13431.574 | V7: =($R$4/$AD$28)*AD7 -> 2804.7533 | W7: 3879.794 | X7: =SUM(U7:W7) -> 20116.121 | Z7: 0.20833333 | AA7: 10 | AC7: 0.20833333 | AD7: 4 | AJ7: June | AK7: 21121.4 | AL7: 7026 | AM7: 2792.7 | AN7: 31814
F8: 3 | G8: 32 | H8: ='STUDY AREA 3'!P96 -> 2317.0991 | I8: kVA | T8: 0.25 | U8: =($R$3/$AA$28)*AA8 -> 18804.204 | V8: =($R$4/$AD$28)*AD8 -> 7011.8832 | W8: 3879.794 | X8: =SUM(U8:W8) -> 29695.881 | Z8: 0.25 | AA8: 14 | AC8: 0.25 | AD8: 10 | AJ8: July | AK8: 21825.55 | AL8: 7260.23 | AM8: 2885.79 | AN8: 32875
F9: 4 | G9: 41 | H9: ='STUDY AREA 4'!P7 -> 2155.441 | I9: kVA | T9: 0.29166667 | U9: =($R$3/$AA$28)*AA9 -> 24176.833 | V9: =($R$4/$AD$28)*AD9 -> 14023.766 | W9: 3879.794 | X9: =SUM(U9:W9) -> 42080.394 | Z9: 0.29166667 | AA9: 18 | AC9: 0.29166667 | AD9: 20 | AJ9: August | AK9: 21825.55 | AL9: 7260.23 | AM9: 2885.79 | AN9: 32875
F10: 4 | G10: 42 | H10: ='STUDY AREA 4'!P56 -> 2155.441 | I10: kVA | T10: 0.33333333 | U10: =($R$3/$AA$28)*AA10 -> 26863.148 | V10: =($R$4/$AD$28)*AD10 -> 21035.649 | W10: 3879.794 | X10: =SUM(U10:W10) -> 51778.592 | Z10: 0.33333333 | AA10: 20 | AC10: 0.33333333 | AD10: 30 | AJ10: September | AK10: 21121.4 | AL10: 7026 | AM10: 2792.7 | AN10: 31814
T11: 0.375 | U11: =($R$3/$AA$28)*AA11 -> 25519.991 | V11: =($R$4/$AD$28)*AD11 -> 24541.591 | W11: 3879.794 | X11: =SUM(U11:W11) -> 53941.376 | Z11: 0.375 | AA11: 19 | AC11: 0.375 | AD11: 35 | AJ11: October | AK11: 21825.55 | AL11: 7260.23 | AM11: 2885.79 | AN11: 32875
A12: Row Labels | B12: Sum of LOAD SIZE | C12: Total Load | T12: 0.41666667 | U12: =($R$3/$AA$28)*AA12 -> 22833.676 | V12: =($R$4/$AD$28)*AD12 -> 28047.533 | W12: 3879.794 | X12: =SUM(U12:W12) -> 54761.003 | Z12: 0.41666667 | AA12: 17 | AC12: 0.41666667 | AD12: 40 | AJ12: November | AK12: 21121.4 | AL12: 7026 | AM12: 2792.7 | AN12: 31814
A13: 1 | B13: 3179.2755 | C13: =B13+B3 -> 8316.171 | T13: 0.45833333 | U13: =($R$3/$AA$28)*AA13 -> 21490.519 | V13: =($R$4/$AD$28)*AD13 -> 29449.909 | W13: 3879.794 | X13: =SUM(U13:W13) -> 54820.222 | Z13: 0.45833333 | AA13: 16 | AC13: 0.45833333 | AD13: 42 | AJ13: December | AK13: 21825.55 | AL13: 7260.23 | AM13: 2885.79 | AN13: 32875
A14: 2 | B14: 3879.7938 | C14: =B14+B4 -> 8204.9302 | T14: 0.5 | U14: =($R$3/$AA$28)*AA14 -> 20147.361 | V14: =($R$4/$AD$28)*AD14 -> 30151.098 | W14: 3879.794 | X14: =SUM(U14:W14) -> 54178.253 | Z14: 0.5 | AA14: 15 | AC14: 0.5 | AD14: 43
A15: 3 | B15: 4472.5401 | C15: =B15+B5 -> 7735.9226 | T15: 0.54166667 | U15: =($R$3/$AA$28)*AA15 -> 20147.361 | V15: =($R$4/$AD$28)*AD15 -> 29449.909 | W15: 3879.794 | X15: =SUM(U15:W15) -> 53477.064 | Z15: 0.54166667 | AA15: 15 | AC15: 0.54166667 | AD15: 42
A16: 4 | B16: 4310.882 | C16: =B16+B6 -> 8337.6391 | T16: 0.58333333 | U16: =($R$3/$AA$28)*AA16 -> 20147.361 | V16: =($R$4/$AD$28)*AD16 -> 28047.533 | W16: 3879.794 | X16: =SUM(U16:W16) -> 52074.688 | Z16: 0.58333333 | AA16: 15 | AC16: 0.58333333 | AD16: 40
A17: Grand Total | B17: 15842.491 | T17: 0.625 | U17: =($R$3/$AA$28)*AA17 -> 21490.519 | V17: =($R$4/$AD$28)*AD17 -> 26645.156 | W17: 3879.794 | X17: =SUM(U17:W17) -> 52015.469 | Z17: 0.625 | AA17: 16 | AC17: 0.625 | AD17: 38
T18: 0.66666667 | U18: =($R$3/$AA$28)*AA18 -> 24176.833 | V18: =($R$4/$AD$28)*AD18 -> 24541.591 | W18: 3879.794 | X18: =SUM(U18:W18) -> 52598.218 | Z18: 0.66666667 | AA18: 18 | AC18: 0.66666667 | AD18: 35
T19: 0.70833333 | U19: =($R$3/$AA$28)*AA19 -> 26863.148 | V19: =($R$4/$AD$28)*AD19 -> 21035.649 | W19: 3879.794 | X19: =SUM(U19:W19) -> 51778.592 | Z19: 0.70833333 | AA19: 20 | AC19: 0.70833333 | AD19: 30
D20: 1 | E20: 8316.171 | T20: 0.75 | U20: =($R$3/$AA$28)*AA20 -> 29549.463 | V20: =($R$4/$AD$28)*AD20 -> 17529.708 | W20: 3879.794 | X20: =SUM(U20:W20) -> 50958.965 | Z20: 0.75 | AA20: 22 | AC20: 0.75 | AD20: 25
D21: 2 | E21: 8204.9302 | T21: 0.79166667 | U21: =($R$3/$AA$28)*AA21 -> 33578.935 | V21: =($R$4/$AD$28)*AD21 -> 14023.766 | W21: 3879.794 | X21: =SUM(U21:W21) -> 51482.496 | Z21: 0.79166667 | AA21: 25 | AC21: 0.79166667 | AD21: 20
D22: 3 | E22: 7735.9226 | T22: 0.83333333 | U22: =($R$3/$AA$28)*AA22 -> 36265.25 | V22: =($R$4/$AD$28)*AD22 -> 10517.825 | W22: 3879.794 | X22: =SUM(U22:W22) -> 50662.869 | Z22: 0.83333333 | AA22: 27 | AC22: 0.83333333 | AD22: 15
D23: 4 | E23: 8337.6391 | T23: 0.875 | U23: =($R$3/$AA$28)*AA23 -> 34922.093 | V23: =($R$4/$AD$28)*AD23 -> 7011.8832 | W23: 3879.794 | X23: =SUM(U23:W23) -> 45813.77 | Z23: 0.875 | AA23: 26 | AC23: 0.875 | AD23: 10
T24: 0.91666667 | U24: =($R$3/$AA$28)*AA24 -> 29549.463 | V24: =($R$4/$AD$28)*AD24 -> 4207.1299 | W24: 3879.794 | X24: =SUM(U24:W24) -> 37636.387 | Z24: 0.91666667 | AA24: 22 | AC24: 0.91666667 | AD24: 6
T25: 0.95833333 | U25: =($R$3/$AA$28)*AA25 -> 13431.574 | V25: =($R$4/$AD$28)*AD25 -> 3505.9416 | W25: 3879.794 | X25: =SUM(U25:W25) -> 20817.31 | Z25: 0.95833333 | AA25: 10 | AC25: 0.95833333 | AD25: 5
T27: Average | U27: =AVERAGE(U2:U25) -> 21770.343 | V27: =AVERAGE(V2:V25) -> 14871.036 | W27: =AVERAGE(W2:W25) -> 3879.794 | X27: =AVERAGE(X2:X25) -> 40521.173
T28: Load Factor | U28: =U27/MAX(U2:U25) -> 0.60030864 | V28: =V27/MAX(V2:V25) -> 0.49321705 | W28: =W27/MAX(W2:W25) -> 1 | X28: =X27/MAX(X2:X25) -> 0.73916469 | Z28: max | AA28: =MAX(AA2:AA25) -> 27 | AC28: max | AD28: =MAX(AD2:AD25) -> 43

Sheet POWERPLANT
A1: Load Type | B1: Fuel Type | C1: Capacity | E1: Efficiency
C2: Installed(kVA) | D2: Dependable(kVA)
A3: Base Load | B3: Coal Fired | C3: 35000 | D3: =C3*E3 -> 32900 | E3: 0.94
A4: Peak Load | B4: Solar | C4: 30000 | D4: =C4*E4 -> 24000 | E4: 0.8

Sheet BREAKERS
B2: Vprimary | C2: =460 -> 460 | L2: Vprimary | M2: =460 -> 460 | V2: Vprimary | W2: =460 -> 460 | AF2: Vprimary | AG2: =460 -> 460
B3: Vsecondary | C3: =230 -> 230 | L3: Vsecondary | M3: =230 -> 230 | V3: Vsecondary | W3: =230 -> 230 | AF3: Vsecondary | AG3: =230 -> 230
B5: STUDY AREA 1 | L5: STUDY AREA 2 | V5: STUDY AREA 3 | AF5: STUDY AREA 4
C6: HIGH VOLTAGE | M6: HIGH VOLTAGE | W6: HIGH VOLTAGE | AG6: HIGH VOLTAGE
C7: kVA | D7: IFLC(HV) | E7: CB=1.25*IFLC(HV) | F7: Standard CB Size | G7: Breaker Type | H7: Impedance | I7: IFAULT | J7: KAIC Rating(kA) | M7: kVA | N7: IFLC(HV) | O7: CB=1.25*IFLC(HV) | P7: Standard CB Size | Q7: Breaker Type | R7: Impedance | S7: IFAULT | T7: KAIC Rating(kA) | W7: kVA | X7: IFLC(HV) | Y7: CB=1.25*IFLC(HV) | Z7: Standard CB Size | AA7: Breaker Type | AB7: Impedance | AC7: IFAULT | AD7: KAIC Rating(kA) | AG7: kVA | AH7: IFLC(HV) | AI7: CB=1.25*IFLC(HV) | AJ7: Standard CB Size | AK7: Breaker Type | AL7: Impedance | AM7: IFAULT | AN7: KAIC Rating(kA)
