Workbook

Sheet DASHBOARD

Sheet DATA AND SCENARIO
A1: Component | B1: No. of Customer/s | C1: Load Connected (kW) | E1: Component | F1: ʎ(f/yr) | G1: r(hrs) | I1: Case | J1: Scenario | L1: Switching Time
A2: M1 | B2: 34855 | C2: 19085.83 | E2: A-B | F2: 0.6 | G2: 2.5 | I2: Base Case | J2: Base Scenario | L2: 0.333hrs
A3: M2 | B3: 1 | C3: 2585.36 | E3: B-C | F3: 0.4 | G3: 2 | I3: Case01 | J3: Switch@ B-C
A4: M3 | B4: 7899 | C4: 2575.86 | E4: C-D | F4: 0.4 | G4: 2 | I4: Case 02 | J4: Case 01 & Switch @ C-D
A5: M4 | B5: 8746 | C5: 9494.65 | E5: B-E | F5: 0.3 | G5: 4 | I5: Case03 | J5: Case 02 & Switch @ B-E
A6: M5 | B6: 11141 | C6: 3741.32 | E6: E-F | F6: 0.3 | G6: 3 | I6: Case04 | J6: Case 03 & Switch @ E-F
A7: M6 | B7: 7223 | C7: 2795.99 | E7: F-G | F7: 0.6 | G7: 2.5 | I7: Case05 | J7: Case 04 & Switch @ F-G
A8: M7 | B8: 32947 | C8: 9850.62 | E8: F-H | F8: 0.5 | G8: 3 | I8: Case06 | J8: Case 05 & Switch @ F-H
A9: M8 | B9: 1 | C9: 1710.77 | E9: H-I | F9: 0.3 | G9: 3 | I9: Case07 | J9: Case 06 & Switch @ H-I
E10: I-J | F10: 0.2 | G10: 1 | I10: Case08 | J10: Case 07 & Switch @ I-K
E11: I-K | F11: 0.3 | G11: 2.5

Sheet RELIABILITY INDICES
A2: Base Case | D2: LOAD Pt. M1 | G2: LOAD Pt. M2 | J2: LOAD Pt. M3 | M2: LOAD Pt. M4 | P2: LOAD Pt. M5 | S2: LOAD Pt. M6 | V2: LOAD Pt. M7 | Y2: LOAD Pt. M8
B3: COMPONENT FAILURE | D3: ʎ (f/yr) | E3: r (hrs) | F3: U (hours/year) | G3: ʎ (f/yr) | H3: r (hrs) | I3: U (hours/year) | J3: ʎ (f/yr) | K3: r (hrs) | L3: U (hours/year) | M3: ʎ (f/yr) | N3: r (hrs) | O3: U (hours/year) | P3: ʎ (f/yr) | Q3: r (hrs) | R3: U (hours/year) | S3: ʎ (f/yr) | T3: r (hrs) | U3: U (hours/year) | V3: ʎ (f/yr) | W3: r (hrs) | X3: U (hours/year) | Y3: ʎ (f/yr) | Z3: r (hrs) | AA3: U (hours/year)
B4: MAIN | C4: {='DATA AND SCENARIO'!$E$2:$E$11} -> A-B | D4: {='DATA AND SCENARIO'!$F$2:$F$11} -> 0.6 | E4: 2.5 | F4: =D4*E4 -> 1.5 | G4: {='DATA AND SCENARIO'!$F$2:$F$11} -> 0.6 | H4: 2.5 | I4: =G4*H4 -> 1.5 | J4: {='DATA AND SCENARIO'!$F$2:$F$11} -> 0.6 | K4: 2.5 | L4: =J4*K4 -> 1.5 | M4: {='DATA AND SCENARIO'!$F$2:$F$11} -> 0.6 | N4: 2.5 | O4: =M4*N4 -> 1.5 | P4: {='DATA AND SCENARIO'!$F$2:$F$11} -> 0.6 | Q4: 2.5 | R4: =P4*Q4 -> 1.5 | S4: {='DATA AND SCENARIO'!$F$2:$F$11} -> 0.6 | T4: 2.5 | U4: =S4*T4 -> 1.5 | V4: {='DATA AND SCENARIO'!$F$2:$F$11} -> 0.6 | W4: 2.5 | X4: =V4*W4 -> 1.5 | Y4: {='DATA AND SCENARIO'!$F$2:$F$11} -> 0.6 | Z4: 2.5 | AA4: =Y4*Z4 -> 1.5
C5: B-C | D5: 0.4 | E5: 2 | F5: =D5*E5 -> 0.8 | G5: 0.4 | H5: 2 | I5: =G5*H5 -> 0.8 | J5: 0.4 | K5: 2 | L5: =J5*K5 -> 0.8 | M5: 0.4 | N5: 2 | O5: =M5*N5 -> 0.8 | P5: 0.4 | Q5: 2 | R5: =P5*Q5 -> 0.8 | S5: 0.4 | T5: 2 | U5: =S5*T5 -> 0.8 | V5: 0.4 | W5: 2 | X5: =V5*W5 -> 0.8 | Y5: 0.4 | Z5: 2 | AA5: =Y5*Z5 -> 0.8
C6: C-D | D6: 0.4 | E6: 2 | F6: =D6*E6 -> 0.8 | G6: 0.4 | H6: 2 | I6: =G6*H6 -> 0.8 | J6: 0.4 | K6: 2 | L6: =J6*K6 -> 0.8 | M6: 0.4 | N6: 2 | O6: =M6*N6 -> 0.8 | P6: 0.4 | Q6: 2 | R6: =P6*Q6 -> 0.8 | S6: 0.4 | T6: 2 | U6: =S6*T6 -> 0.8 | V6: 0.4 | W6: 2 | X6: =V6*W6 -> 0.8 | Y6: 0.4 | Z6: 2 | AA6: =Y6*Z6 -> 0.8
C7: B-E | D7: 0.3 | E7: 4 | F7: =D7*E7 -> 1.2 | G7: 0.3 | H7: 4 | I7: =G7*H7 -> 1.2 | J7: 0.3 | K7: 4 | L7: =J7*K7 -> 1.2 | M7: 0.3 | N7: 4 | O7: =M7*N7 -> 1.2 | P7: 0.3 | Q7: 4 | R7: =P7*Q7 -> 1.2 | S7: 0.3 | T7: 4 | U7: =S7*T7 -> 1.2 | V7: 0.3 | W7: 4 | X7: =V7*W7 -> 1.2 | Y7: 0.3 | Z7: 4 | AA7: =Y7*Z7 -> 1.2
C8: E-F | D8: 0.3 | E8: 3 | F8: =D8*E8 -> 0.9 | G8: 0.3 | H8: 3 | I8: =G8*H8 -> 0.9 | J8: 0.3 | K8: 3 | L8: =J8*K8 -> 0.9 | M8: 0.3 | N8: 3 | O8: =M8*N8 -> 0.9 | P8: 0.3 | Q8: 3 | R8: =P8*Q8 -> 0.9 | S8: 0.3 | T8: 3 | U8: =S8*T8 -> 0.9 | V8: 0.3 | W8: 3 | X8: =V8*W8 -> 0.9 | Y8: 0.3 | Z8: 3 | AA8: =Y8*Z8 -> 0.9
C9: F-G | D9: 0.6 | E9: 2.5 | F9: =D9*E9 -> 1.5 | G9: 0.6 | H9: 2.5 | I9: =G9*H9 -> 1.5 | J9: 0.6 | K9: 2.5 | L9: =J9*K9 -> 1.5 | M9: 0.6 | N9: 2.5 | O9: =M9*N9 -> 1.5 | P9: 0.6 | Q9: 2.5 | R9: =P9*Q9 -> 1.5 | S9: 0.6 | T9: 2.5 | U9: =S9*T9 -> 1.5 | V9: 0.6 | W9: 2.5 | X9: =V9*W9 -> 1.5 | Y9: 0.6 | Z9: 2.5 | AA9: =Y9*Z9 -> 1.5
C10: F-H | D10: 0.5 | E10: 3 | F10: =D10*E10 -> 1.5 | G10: 0.5 | H10: 3 | I10: =G10*H10 -> 1.5 | J10: 0.5 | K10: 3 | L10: =J10*K10 -> 1.5 | M10: 0.5 | N10: 3 | O10: =M10*N10 -> 1.5 | P10: 0.5 | Q10: 3 | R10: =P10*Q10 -> 1.5 | S10: 0.5 | T10: 3 | U10: =S10*T10 -> 1.5 | V10: 0.5 | W10: 3 | X10: =V10*W10 -> 1.5 | Y10: 0.5 | Z10: 3 | AA10: =Y10*Z10 -> 1.5
C11: H-I | D11: 0.3 | E11: 3 | F11: =D11*E11 -> 0.9 | G11: 0.3 | H11: 3 | I11: =G11*H11 -> 0.9 | J11: 0.3 | K11: 3 | L11: =J11*K11 -> 0.9 | M11: 0.3 | N11: 3 | O11: =M11*N11 -> 0.9 | P11: 0.3 | Q11: 3 | R11: =P11*Q11 -> 0.9 | S11: 0.3 | T11: 3 | U11: =S11*T11 -> 0.9 | V11: 0.3 | W11: 3 | X11: =V11*W11 -> 0.9 | Y11: 0.3 | Z11: 3 | AA11: =Y11*Z11 -> 0.9
C12: I-J | D12: 0.2 | E12: 1 | F12: =D12*E12 -> 0.2 | G12: 0.2 | H12: 1 | I12: =G12*H12 -> 0.2 | J12: 0.2 | K12: 1 | L12: =J12*K12 -> 0.2 | M12: 0.2 | N12: 1 | O12: =M12*N12 -> 0.2 | P12: 0.2 | Q12: 1 | R12: =P12*Q12 -> 0.2 | S12: 0.2 | T12: 1 | U12: =S12*T12 -> 0.2 | V12: 0.2 | W12: 1 | X12: =V12*W12 -> 0.2 | Y12: 0.2 | Z12: 1 | AA12: =Y12*Z12 -> 0.2
C13: I-K | D13: 0.3 | E13: 2.5 | F13: =D13*E13 -> 0.75 | G13: 0.3 | H13: 2.5 | I13: =G13*H13 -> 0.75 | J13: 0.3 | K13: 2.5 | L13: =J13*K13 -> 0.75 | M13: 0.3 | N13: 2.5 | O13: =M13*N13 -> 0.75 | P13: 0.3 | Q13: 2.5 | R13: =P13*Q13 -> 0.75 | S13: 0.3 | T13: 2.5 | U13: =S13*T13 -> 0.75 | V13: 0.3 | W13: 2.5 | X13: =V13*W13 -> 0.75 | Y13: 0.3 | Z13: 2.5 | AA13: =Y13*Z13 -> 0.75
C14: TOTAL | D14: =SUM(_xlfn.ANCHORARRAY(D4)) -> 3.9 | E14: =F14/D14 -> 2.5769231 | F14: =SUM(F4:F13) -> 10.05 | G14: =SUM(_xlfn.ANCHORARRAY(G4)) -> 3.9 | H14: =I14/G14 -> 2.5769231 | I14: =SUM(I4:I13) -> 10.05 | J14: =SUM(_xlfn.ANCHORARRAY(J4)) -> 3.9 | K14: =L14/J14 -> 2.5769231 | L14: =SUM(L4:L13) -> 10.05 | M14: =SUM(_xlfn.ANCHORARRAY(M4)) -> 3.9 | N14: =O14/M14 -> 2.5769231 | O14: =SUM(O4:O13) -> 10.05 | P14: =SUM(_xlfn.ANCHORARRAY(P4)) -> 3.9 | Q14: =R14/P14 -> 2.5769231 | R14: =SUM(R4:R13) -> 10.05 | S14: =SUM(_xlfn.ANCHORARRAY(S4)) -> 3.9 | T14: =U14/S14 -> 2.5769231 | U14: =SUM(U4:U13) -> 10.05 | V14: =SUM(_xlfn.ANCHORARRAY(V4)) -> 3.9 | W14: =X14/V14 -> 2.5769231 | X14: =SUM(X4:X13) -> 10.05 | Y14: =SUM(_xlfn.ANCHORARRAY(Y4)) -> 3.9 | Z14: =AA14/Y14 -> 2.5769231 | AA14: =SUM(AA4:AA13) -> 10.05
A17: Case 1 | D17: LOAD Pt. M1 | G17: LOAD Pt. M2 | J17: LOAD Pt. M3 | M17: LOAD Pt. M4 | P17: LOAD Pt. M5 | S17: LOAD Pt. M6 | V17: LOAD Pt. M7 | Y17: LOAD Pt. M8
B18: COMPONENT FAILURE | D18: ʎ (f/yr) | E18: r (hrs) | F18: U (hours/year) | G18: ʎ (f/yr) | H18: r (hrs) | I18: U (hours/year) | J18: ʎ (f/yr) | K18: r (hrs) | L18: U (hours/year) | M18: ʎ (f/yr) | N18: r (hrs) | O18: U (hours/year) | P18: ʎ (f/yr) | Q18: r (hrs) | R18: U (hours/year) | S18: ʎ (f/yr) | T18: r (hrs) | U18: U (hours/year) | V18: ʎ (f/yr) | W18: r (hrs) | X18: U (hours/year) | Y18: ʎ (f/yr) | Z18: r (hrs) | AA18: U (hours/year)
B19: MAIN | C19: {='DATA AND SCENARIO'!$E$2:$E$11} -> A-B | D19: {='DATA AND SCENARIO'!$F$2:$F$11} -> 0.6 | E19: 2.5 | F19: =D19*E19 -> 1.5 | G19: {='DATA AND SCENARIO'!$F$2:$F$11} -> 0.6 | H19: 2.5 | I19: =G19*H19 -> 1.5 | J19: {='DATA AND SCENARIO'!$F$2:$F$11} -> 0.6 | K19: 2.5 | L19: =J19*K19 -> 1.5 | M19: {='DATA AND SCENARIO'!$F$2:$F$11} -> 0.6 | N19: 2.5 | O19: =M19*N19 -> 1.5 | P19: {='DATA AND SCENARIO'!$F$2:$F$11} -> 0.6 | Q19: 2.5 | R19: =P19*Q19 -> 1.5 | S19: {='DATA AND SCENARIO'!$F$2:$F$11} -> 0.6 | T19: 2.5 | U19: =S19*T19 -> 1.5 | V19: {='DATA AND SCENARIO'!$F$2:$F$11} -> 0.6 | W19: 2.5 | X19: =V19*W19 -> 1.5 | Y19: {='DATA AND SCENARIO'!$F$2:$F$11} -> 0.6 | Z19: 2.5 | AA19: =Y19*Z19 -> 1.5
C20: B-C | D20: 0.4 | E20: 0.333 | F20: =D20*E20 -> 0.1332 | G20: 0.4 | H20: 2 | I20: =G20*H20 -> 0.8 | J20: 0.4 | K20: 2 | L20: =J20*K20 -> 0.8 | M20: 0.4 | N20: 0.333 | O20: =M20*N20 -> 0.1332 | P20: 0.4 | Q20: 0.333 | R20: =P20*Q20 -> 0.1332 | S20: 0.4 | T20: 0.333 | U20: =S20*T20 -> 0.1332 | V20: 0.4 | W20: 0.333 | X20: =V20*W20 -> 0.1332 | Y20: 0.4 | Z20: 0.333 | AA20: =Y20*Z20 -> 0.1332
C21: C-D | D21: 0.4 | E21: 0.333 | F21: =D21*E21 -> 0.1332 | G21: 0.4 | H21: 2 | I21: =G21*H21 -> 0.8 | J21: 0.4 | K21: 2 | L21: =J21*K21 -> 0.8 | M21: 0.4 | N21: 0.333 | O21: =M21*N21 -> 0.1332 | P21: 0.4 | Q21: 0.333 | R21: =P21*Q21 -> 0.1332 | S21: 0.4 | T21: 0.333 | U21: =S21*T21 -> 0.1332 | V21: 0.4 | W21: 0.333 | X21: =V21*W21 -> 0.1332 | Y21: 0.4 | Z21: 0.333 | AA21: =Y21*Z21 -> 0.1332
C22: B-E | D22: 0.3 | E22: 4 | F22: =D22*E22 -> 1.2 | G22: 0.3 | H22: 4 | I22: =G22*H22 -> 1.2 | J22: 0.3 | K22: 4 | L22: =J22*K22 -> 1.2 | M22: 0.3 | N22: 4 | O22: =M22*N22 -> 1.2 | P22: 0.3 | Q22: 4 | R22: =P22*Q22 -> 1.2 | S22: 0.3 | T22: 4 | U22: =S22*T22 -> 1.2 | V22: 0.3 | W22: 4 | X22: =V22*W22 -> 1.2 | Y22: 0.3 | Z22: 4 | AA22: =Y22*Z22 -> 1.2
C23: E-F | D23: 0.3 | E23: 3 | F23: =D23*E23 -> 0.9 | G23: 0.3 | H23: 3 | I23: =G23*H23 -> 0.9 | J23: 0.3 | K23: 3 | L23: =J23*K23 -> 0.9 | M23: 0.3 | N23: 3 | O23: =M23*N23 -> 0.9 | P23: 0.3 | Q23: 3 | R23: =P23*Q23 -> 0.9 | S23: 0.3 | T23: 3 | U23: =S23*T23 -> 0.9 | V23: 0.3 | W23: 3 | X23: =V23*W23 -> 0.9 | Y23: 0.3 | Z23: 3 | AA23: =Y23*Z23 -> 0.9
C24: F-G | D24: 0.6 | E24: 2.5 | F24: =D24*E24 -> 1.5 | G24: 0.6 | H24: 2.5 | I24: =G24*H24 -> 1.5 | J24: 0.6 | K24: 2.5 | L24: =J24*K24 -> 1.5 | M24: 0.6 | N24: 2.5 | O24: =M24*N24 -> 1.5 | P24: 0.6 | Q24: 2.5 | R24: =P24*Q24 -> 1.5 | S24: 0.6 | T24: 2.5 | U24: =S24*T24 -> 1.5 | V24: 0.6 | W24: 2.5 | X24: =V24*W24 -> 1.5 | Y24: 0.6 | Z24: 2.5 | AA24: =Y24*Z24 -> 1.5
C25: F-H | D25: 0.5 | E25: 3 | F25: =D25*E25 -> 1.5 | G25: 0.5 | H25: 3 | I25: =G25*H25 -> 1.5 | J25: 0.5 | K25: 3 | L25: =J25*K25 -> 1.5 | M25: 0.5 | N25: 3 | O25: =M25*N25 -> 1.5 | P25: 0.5 | Q25: 3 | R25: =P25*Q25 -> 1.5 | S25: 0.5 | T25: 3 | U25: =S25*T25 -> 1.5 | V25: 0.5 | W25: 3 | X25: =V25*W25 -> 1.5 | Y25: 0.5 | Z25: 3 | AA25: =Y25*Z25 -> 1.5
C26: H-I | D26: 0.3 | E26: 3 | F26: =D26*E26 -> 0.9 | G26: 0.3 | H26: 3 | I26: =G26*H26 -> 0.9 | J26: 0.3 | K26: 3 | L26: =J26*K26 -> 0.9 | M26: 0.3 | N26: 3 | O26: =M26*N26 -> 0.9 | P26: 0.3 | Q26: 3 | R26: =P26*Q26 -> 0.9 | S26: 0.3 | T26: 3 | U26: =S26*T26 -> 0.9 | V26: 0.3 | W26: 3 | X26: =V26*W26 -> 0.9 | Y26: 0.3 | Z26: 3 | AA26: =Y26*Z26 -> 0.9
C27: I-J | D27: 0.2 | E27: 1 | F27: =D27*E27 -> 0.2 | G27: 0.2 | H27: 1 | I27: =G27*H27 -> 0.2 | J27: 0.2 | K27: 1 | L27: =J27*K27 -> 0.2 | M27: 0.2 | N27: 1 | O27: =M27*N27 -> 0.2 | P27: 0.2 | Q27: 1 | R27: =P27*Q27 -> 0.2 | S27: 0.2 | T27: 1 | U27: =S27*T27 -> 0.2 | V27: 0.2 | W27: 1 | X27: =V27*W27 -> 0.2 | Y27: 0.2 | Z27: 1 | AA27: =Y27*Z27 -> 0.2
C28: I-K | D28: 0.3 | E28: 2.5 | F28: =D28*E28 -> 0.75 | G28: 0.3 | H28: 2.5 | I28: =G28*H28 -> 0.75 | J28: 0.3 | K28: 2.5 | L28: =J28*K28 -> 0.75 | M28: 0.3 | N28: 2.5 | O28: =M28*N28 -> 0.75 | P28: 0.3 | Q28: 2.5 | R28: =P28*Q28 -> 0.75 | S28: 0.3 | T28: 2.5 | U28: =S28*T28 -> 0.75 | V28: 0.3 | W28: 2.5 | X28: =V28*W28 -> 0.75 | Y28: 0.3 | Z28: 2.5 | AA28: =Y28*Z28 -> 0.75
C29: TOTAL | D29: =SUM(_xlfn.ANCHORARRAY(D19)) -> 3.9 | E29: =F29/D29 -> 2.2349744 | F29: =SUM(F19:F28) -> 8.7164 | G29: =SUM(_xlfn.ANCHORARRAY(G19)) -> 3.9 | H29: =I29/G29 -> 2.5769231 | I29: =SUM(I19:I28) -> 10.05 | J29: =SUM(_xlfn.ANCHORARRAY(J19)) -> 3.9 | K29: =L29/J29 -> 2.5769231 | L29: =SUM(L19:L28) -> 10.05 | M29: =SUM(_xlfn.ANCHORARRAY(M19)) -> 3.9 | N29: =O29/M29 -> 2.2349744 | O29: =SUM(O19:O28) -> 8.7164 | P29: =SUM(_xlfn.ANCHORARRAY(P19)) -> 3.9 | Q29: =R29/P29 -> 2.2349744 | R29: =SUM(R19:R28) -> 8.7164 | S29: =SUM(_xlfn.ANCHORARRAY(S19)) -> 3.9 | T29: =U29/S29 -> 2.2349744 | U29: =SUM(U19:U28) -> 8.7164 | V29: =SUM(_xlfn.ANCHORARRAY(V19)) -> 3.9 | W29: =X29/V29 -> 2.2349744 | X29: =SUM(X19:X28) -> 8.7164 | Y29: =SUM(_xlfn.ANCHORARRAY(Y19)) -> 3.9 | Z29: =AA29/Y29 -> 2.2349744 | AA29: =SUM(AA19:AA28) -> 8.7164
A32: Case 2 | D32: LOAD Pt. M1 | G32: LOAD Pt. M2 | J32: LOAD Pt. M3 | M32: LOAD Pt. M4 | P32: LOAD Pt. M5 | S32: LOAD Pt. M6 | V32: LOAD Pt. M7 | Y32: LOAD Pt. M8
B33: COMPONENT FAILURE | D33: ʎ (f/yr) | E33: r (hrs) | F33: U (hours/year) | G33: ʎ (f/yr) | H33: r (hrs) | I33: U (hours/year) | J33: ʎ (f/yr) | K33: r (hrs) | L33: U (hours/year) | M33: ʎ (f/yr) | N33: r (hrs) | O33: U (hours/year) | P33: ʎ (f/yr) | Q33: r (hrs) | R33: U (hours/year) | S33: ʎ (f/yr) | T33: r (hrs) | U33: U (hours/year) | V33: ʎ (f/yr) | W33: r (hrs) | X33: U (hours/year) | Y33: ʎ (f/yr) | Z33: r (hrs) | AA33: U (hours/year)
B34: MAIN | C34: {='DATA AND SCENARIO'!$E$2:$E$11} -> A-B | D34: {='DATA AND SCENARIO'!$F$2:$F$11} -> 0.6 | E34: 2.5 | F34: =D34*E34 -> 1.5 | G34: {='DATA AND SCENARIO'!$F$2:$F$11} -> 0.6 | H34: 2.5 | I34: =G34*H34 -> 1.5 | J34: {='DATA AND SCENARIO'!$F$2:$F$11} -> 0.6 | K34: 2.5 | L34: =J34*K34 -> 1.5 | M34: {='DATA AND SCENARIO'!$F$2:$F$11} -> 0.6 | N34: 2.5 | O34: =M34*N34 -> 1.5 | P34: {='DATA AND SCENARIO'!$F$2:$F$11} -> 0.6 | Q34: 2.5 | R34: =P34*Q34 -> 1.5 | S34: {='DATA AND SCENARIO'!$F$2:$F$11} -> 0.6 | T34: 2.5 | U34: =S34*T34 -> 1.5 | V34: {='DATA AND SCENARIO'!$F$2:$F$11} -> 0.6 | W34: 2.5 | X34: =V34*W34 -> 1.5 | Y34: {='DATA AND SCENARIO'!$F$2:$F$11} -> 0.6 | Z34: 2.5 | AA34: =Y34*Z34 -> 1.5
C35: B-C | D35: 0.4 | E35: 0.333 | F35: =D35*E35 -> 0.1332 | G35: 0.4 | H35: 2 | I35: =G35*H35 -> 0.8 | J35: 0.4 | K35: 2 | L35: =J35*K35 -> 0.8 | M35: 0.4 | N35: 0.333 | O35: =M35*N35 -> 0.1332 | P35: 0.4 | Q35: 0.333 | R35: =P35*Q35 -> 0.1332 | S35: 0.4 | T35: 0.333 | U35: =S35*T35 -> 0.1332 | V35: 0.4 | W35: 0.333 | X35: =V35*W35 -> 0.1332 | Y35: 0.4 | Z35: 0.333 | AA35: =Y35*Z35 -> 0.1332
C36: C-D | D36: 0.4 | E36: 0.333 | F36: =D36*E36 -> 0.1332 | G36: 0.4 | H36: 0.333 | I36: =G36*H36 -> 0.1332 | J36: 0.4 | K36: 2 | L36: =J36*K36 -> 0.8 | M36: 0.4 | N36: 0.333 | O36: =M36*N36 -> 0.1332 | P36: 0.4 | Q36: 0.333 | R36: =P36*Q36 -> 0.1332 | S36: 0.4 | T36: 0.333 | U36: =S36*T36 -> 0.1332 | V36: 0.4 | W36: 0.333 | X36: =V36*W36 -> 0.1332 | Y36: 0.4 | Z36: 0.333 | AA36: =Y36*Z36 -> 0.1332
C37: B-E | D37: 0.3 | E37: 4 | F37: =D37*E37 -> 1.2 | G37: 0.3 | H37: 4 | I37: =G37*H37 -> 1.2 | J37: 0.3 | K37: 4 | L37: =J37*K37 -> 1.2 | M37: 0.3 | N37: 4 | O37: =M37*N37 -> 1.2 | P37: 0.3 | Q37: 4 | R37: =P37*Q37 -> 1.2 | S37: 0.3 | T37: 4 | U37: =S37*T37 -> 1.2 | V37: 0.3 | W37: 4 | X37: =V37*W37 -> 1.2 | Y37: 0.3 | Z37: 4 | AA37: =Y37*Z37 -> 1.2
C38: E-F | D38: 0.3 | E38: 3 | F38: =D38*E38 -> 0.9 | G38: 0.3 | H38: 3 | I38: =G38*H38 -> 0.9 | J38: 0.3 | K38: 3 | L38: =J38*K38 -> 0.9 | M38: 0.3 | N38: 3 | O38: =M38*N38 -> 0.9 | P38: 0.3 | Q38: 3 | R38: =P38*Q38 -> 0.9 | S38: 0.3 | T38: 3 | U38: =S38*T38 -> 0.9 | V38: 0.3 | W38: 3 | X38: =V38*W38 -> 0.9 | Y38: 0.3 | Z38: 3 | AA38: =Y38*Z38 -> 0.9
C39: F-G | D39: 0.6 | E39: 2.5 | F39: =D39*E39 -> 1.5 | G39: 0.6 | H39: 2.5 | I39: =G39*H39 -> 1.5 | J39: 0.6 | K39: 2.5 | L39: =J39*K39 -> 1.5 | M39: 0.6 | N39: 2.5 | O39: =M39*N39 -> 1.5 | P39: 0.6 | Q39: 2.5 | R39: =P39*Q39 -> 1.5 | S39: 0.6 | T39: 2.5 | U39: =S39*T39 -> 1.5 | V39: 0.6 | W39: 2.5 | X39: =V39*W39 -> 1.5 | Y39: 0.6 | Z39: 2.5 | AA39: =Y39*Z39 -> 1.5
C40: F-H | D40: 0.5 | E40: 3 | F40: =D40*E40 -> 1.5 | G40: 0.5 | H40: 3 | I40: =G40*H40 -> 1.5 | J40: 0.5 | K40: 3 | L40: =J40*K40 -> 1.5 | M40: 0.5 | N40: 3 | O40: =M40*N40 -> 1.5 | P40: 0.5 | Q40: 3 | R40: =P40*Q40 -> 1.5 | S40: 0.5 | T40: 3 | U40: =S40*T40 -> 1.5 | V40: 0.5 | W40: 3 | X40: =V40*W40 -> 1.5 | Y40: 0.5 | Z40: 3 | AA40: =Y40*Z40 -> 1.5
C41: H-I | D41: 0.3 | E41: 3 | F41: =D41*E41 -> 0.9 | G41: 0.3 | H41: 3 | I41: =G41*H41 -> 0.9 | J41: 0.3 | K41: 3 | L41: =J41*K41 -> 0.9 | M41: 0.3 | N41: 3 | O41: =M41*N41 -> 0.9 | P41: 0.3 | Q41: 3 | R41: =P41*Q41 -> 0.9 | S41: 0.3 | T41: 3 | U41: =S41*T41 -> 0.9 | V41: 0.3 | W41: 3 | X41: =V41*W41 -> 0.9 | Y41: 0.3 | Z41: 3 | AA41: =Y41*Z41 -> 0.9
C42: I-J | D42: 0.2 | E42: 1 | F42: =D42*E42 -> 0.2 | G42: 0.2 | H42: 1 | I42: =G42*H42 -> 0.2 | J42: 0.2 | K42: 1 | L42: =J42*K42 -> 0.2 | M42: 0.2 | N42: 1 | O42: =M42*N42 -> 0.2 | P42: 0.2 | Q42: 1 | R42: =P42*Q42 -> 0.2 | S42: 0.2 | T42: 1 | U42: =S42*T42 -> 0.2 | V42: 0.2 | W42: 1 | X42: =V42*W42 -> 0.2 | Y42: 0.2 | Z42: 1 | AA42: =Y42*Z42 -> 0.2
C43: I-K | D43: 0.3 | E43: 2.5 | F43: =D43*E43 -> 0.75 | G43: 0.3 | H43: 2.5 | I43: =G43*H43 -> 0.75 | J43: 0.3 | K43: 2.5 | L43: =J43*K43 -> 0.75 | M43: 0.3 | N43: 2.5 | O43: =M43*N43 -> 0.75 | P43: 0.3 | Q43: 2.5 | R43: =P43*Q43 -> 0.75 | S43: 0.3 | T43: 2.5 | U43: =S43*T43 -> 0.75 | V43: 0.3 | W43: 2.5 | X43: =V43*W43 -> 0.75 | Y43: 0.3 | Z43: 2.5 | AA43: =Y43*Z43 -> 0.75
C44: TOTAL | D44: =SUM(_xlfn.ANCHORARRAY(D34)) -> 3.9 | E44: =F44/D44 -> 2.2349744 | F44: =SUM(F34:F43) -> 8.7164 | G44: =SUM(_xlfn.ANCHORARRAY(G34)) -> 3.9 | H44: =I44/G44 -> 2.4059487 | I44: =SUM(I34:I43) -> 9.3832 | J44: =SUM(_xlfn.ANCHORARRAY(J34)) -> 3.9 | K44: =L44/J44 -> 2.5769231 | L44: =SUM(L34:L43) -> 10.05 | M44: =SUM(_xlfn.ANCHORARRAY(M34)) -> 3.9 | N44: =O44/M44 -> 2.2349744 | O44: =SUM(O34:O43) -> 8.7164 | P44: =SUM(_xlfn.ANCHORARRAY(P34)) -> 3.9 | Q44: =R44/P44 -> 2.2349744 | R44: =SUM(R34:R43) -> 8.7164 | S44: =SUM(_xlfn.ANCHORARRAY(S34)) -> 3.9 | T44: =U44/S44 -> 2.2349744 | U44: =SUM(U34:U43) -> 8.7164 | V44: =SUM(_xlfn.ANCHORARRAY(V34)) -> 3.9 | W44: =X44/V44 -> 2.2349744 | X44: =SUM(X34:X43) -> 8.7164 | Y44: =SUM(_xlfn.ANCHORARRAY(Y34)) -> 3.9 | Z44: =AA44/Y44 -> 2.2349744 | AA44: =SUM(AA34:AA43) -> 8.7164
A47: Case 3 | D47: LOAD Pt. M1 | G47: LOAD Pt. M2 | J47: LOAD Pt. M3 | M47: LOAD Pt. M4 | P47: LOAD Pt. M5 | S47: LOAD Pt. M6 | V47: LOAD Pt. M7 | Y47: LOAD Pt. M8
...

Sheet RESULTS
B1: Case | C1: SAIFI (int/customer-yr) | D1: SAIDI (hours/customer-yr) | E1: CAIDI (hours/customer-interruption) | F1: ASUI | G1: ASAI | H1: ASCI (kWh/customer-yr) | I1: ENS (kWh) | J1: kWh saved | K1: Number of Switches | L1: kWh per Switch
B2: Base Case | C2: =('RELIABILITY INDICES'!D14*SUM('DATA AND SCENARIO'!B2:B9))/SUM('DATA AND SCENARIO'!B2:B9) -> 3.9 | D2: =(('DATA AND SCENARIO'!B2*C16)+('DATA AND SCENARIO'!B3*C17)+('DATA AND SCENARIO'!B4*C18)+('DATA AND SCENARIO'!B5*C19)+('DATA AND SCENARIO'!B6*C20)+('DATA AND SCENARIO'!B7*C21)+('DATA AND SCENARIO'!B8*C22)+('DATA AND SCENARIO'!B9*C23))/SUM('DATA AND SCENARIO'!B2:B9) -> 10.05 | E2: =D2/C2 -> 2.5769231 | F2: =D2/8760 -> 0.0011472603 | G2: =1-F2 -> 0.99885274 | H2: =(('DATA AND SCENARIO'!$C$2*C16)+('DATA AND SCENARIO'!$C$3*C17)+('DATA AND SCENARIO'!$C$4*C18)+('DATA AND SCENARIO'!$C$5*C19)+('DATA AND SCENARIO'!$C$6*C20)+('DATA AND SCENARIO'!$C$7*C21)+('DATA AND SCENARIO'!$C$8*C22)+('DATA AND SCENARIO'!$C$9*C23))/SUM('DATA AND SCENARIO'!$B$2:$B$9) -> 5.0674138 | I2: =H2*SUM('DATA AND SCENARIO'!$B$2:$B$9) -> 520996.02 | J2: =$I$2-I2 -> 0 | K2: 0 | L2: 0
B3: Case 01 | C3: =('RELIABILITY INDICES'!D14*SUM('DATA AND SCENARIO'!B2:B9))/SUM('DATA AND SCENARIO'!B2:B9) -> 3.9 | D3: =(('DATA AND SCENARIO'!$B$2*F16)+('DATA AND SCENARIO'!$B$3*F17)+('DATA AND SCENARIO'!$B$4*F18)+('DATA AND SCENARIO'!$B$5*F19)+('DATA AND SCENARIO'!$B$6*F20)+('DATA AND SCENARIO'!$B$7*F21)+('DATA AND SCENARIO'!$B$8*F22)+('DATA AND SCENARIO'!$B$9*F23))/SUM('DATA AND SCENARIO'!$B$2:$B$9) -> 8.8188719 | E3: =D3/C3 -> 2.2612492 | F3: =D3/8760 -> 0.0010067205 | G3: =1-F3 -> 0.99899328 | H3: =(('DATA AND SCENARIO'!$C$2*F16)+('DATA AND SCENARIO'!$C$3*F17)+('DATA AND SCENARIO'!$C$4*F18)+('DATA AND SCENARIO'!$C$5*F19)+('DATA AND SCENARIO'!$C$6*F20)+('DATA AND SCENARIO'!$C$7*F21)+('DATA AND SCENARIO'!$C$8*F22)+('DATA AND SCENARIO'!$C$9*F23))/SUM('DATA AND SCENARIO'!$B$2:$B$9) -> 4.4619325 | I3: =H3*SUM('DATA AND SCENARIO'!$B$2:$B$9) -> 458744.67 | J3: =$I$2-I3 -> 62251.354 | K3: 1 | L3: =J3/K3 -> 62251.354
B4: Case 02 | C4: =('RELIABILITY INDICES'!D14*SUM('DATA AND SCENARIO'!B2:B9))/SUM('DATA AND SCENARIO'!B2:B9) -> 3.9 | D4: =(('DATA AND SCENARIO'!$B$2*I16)+('DATA AND SCENARIO'!$B$3*I17)+('DATA AND SCENARIO'!$B$4*I18)+('DATA AND SCENARIO'!$B$5*I19)+('DATA AND SCENARIO'!$B$6*I20)+('DATA AND SCENARIO'!$B$7*I21)+('DATA AND SCENARIO'!$B$8*I22)+('DATA AND SCENARIO'!$B$9*I23))/SUM('DATA AND SCENARIO'!$B$2:$B$9) -> 8.8188654 | E4: =D4/C4 -> 2.2612475 | F4: =D4/8760 -> 0.0010067198 | G4: =1-F4 -> 0.99899328 | H4: =(('DATA AND SCENARIO'!$C$2*I16)+('DATA AND SCENARIO'!$C$3*I17)+('DATA AND SCENARIO'!$C$4*I18)+('DATA AND SCENARIO'!$C$5*I19)+('DATA AND SCENARIO'!$C$6*I20)+('DATA AND SCENARIO'!$C$7*I21)+('DATA AND SCENARIO'!$C$8*I22)+('DATA AND SCENARIO'!$C$9*I23))/SUM('DATA AND SCENARIO'!$B$2:$B$9) -> 4.445165 | I4: =H4*SUM('DATA AND SCENARIO'!$B$2:$B$9) -> 457020.75 | J4: =$I$2-I4 -> 63975.272 | K4: 2 | L4: =J4/K4 -> 31987.636
B5: Case 03 | C5: =('RELIABILITY INDICES'!D59*SUM('DATA AND SCENARIO'!B2:B9))/SUM('DATA AND SCENARIO'!B2:B9) -> 3.9 | D5: =(('DATA AND SCENARIO'!$B$2*L16)+('DATA AND SCENARIO'!$B$3*L17)+('DATA AND SCENARIO'!$B$4*L18)+('DATA AND SCENARIO'!$B$5*L19)+('DATA AND SCENARIO'!$B$6*L20)+('DATA AND SCENARIO'!$B$7*L21)+('DATA AND SCENARIO'!$B$8*L22)+('DATA AND SCENARIO'!$B$9*L23))/SUM('DATA AND SCENARIO'!$B$2:$B$9) -> 6.2748903 | E5: =D5/C5 -> 1.6089462 | F5: =D5/8760 -> 0.00071631168 | G5: =1-F5 -> 0.99928369 | H5: =(('DATA AND SCENARIO'!$C$2*L16)+('DATA AND SCENARIO'!$C$3*L17)+('DATA AND SCENARIO'!$C$4*L18)+('DATA AND SCENARIO'!$C$5*L19)+('DATA AND SCENARIO'!$C$6*L20)+('DATA AND SCENARIO'!$C$7*L21)+('DATA AND SCENARIO'!$C$8*L22)+('DATA AND SCENARIO'!$C$9*L23))/SUM('DATA AND SCENARIO'!$B$2:$B$9) -> 3.0024357 | I5: =H5*SUM('DATA AND SCENARIO'!$B$2:$B$9) -> 308689.42 | J5: =$I$2-I5 -> 212306.6 | K5: 3 | L5: =J5/K5 -> 70768.867
B6: Case 04 | C6: =('RELIABILITY INDICES'!D74*SUM('DATA AND SCENARIO'!B2:B9))/SUM('DATA AND SCENARIO'!B2:B9) -> 3.9 | D6: =(('DATA AND SCENARIO'!$B$2*O16)+('DATA AND SCENARIO'!$B$3*O17)+('DATA AND SCENARIO'!$B$4*O18)+('DATA AND SCENARIO'!$B$5*O19)+('DATA AND SCENARIO'!$B$6*O20)+('DATA AND SCENARIO'!$B$7*O21)+('DATA AND SCENARIO'!$B$8*O22)+('DATA AND SCENARIO'!$B$9*O23))/SUM('DATA AND SCENARIO'!$B$2:$B$9) -> 5.8480748 | E6: =D6/C6 -> 1.4995064 | F6: =D6/8760 -> 0.00066758845 | G6: =1-F6 -> 0.99933241 | H6: =(('DATA AND SCENARIO'!$C$2*O16)+('DATA AND SCENARIO'!$C$3*O17)+('DATA AND SCENARIO'!$C$4*O18)+('DATA AND SCENARIO'!$C$5*O19)+('DATA AND SCENARIO'!$C$6*O20)+('DATA AND SCENARIO'!$C$7*O21)+('DATA AND SCENARIO'!$C$8*O22)+('DATA AND SCENARIO'!$C$9*O23))/SUM('DATA AND SCENARIO'!$B$2:$B$9) -> 2.5390852 | I6: =H6*SUM('DATA AND SCENARIO'!$B$2:$B$9) -> 261050.96 | J6: =$I$2-I6 -> 259945.06 | K6: 4 | L6: =J6/K6 -> 64986.264
B7: Case 05 | C7: =('RELIABILITY INDICES'!D89*SUM('DATA AND SCENARIO'!B3:B10))/SUM('DATA AND SCENARIO'!B3:B10) -> 3.9 | D7: =(('DATA AND SCENARIO'!$B$2*R16)+('DATA AND SCENARIO'!$B$3*R17)+('DATA AND SCENARIO'!$B$4*R18)+('DATA AND SCENARIO'!$B$5*R19)+('DATA AND SCENARIO'!$B$6*R20)+('DATA AND SCENARIO'!$B$7*R21)+('DATA AND SCENARIO'!$B$8*R22)+('DATA AND SCENARIO'!$B$9*R23))/SUM('DATA AND SCENARIO'!$B$2:$B$9) -> 5.3400619 | E7: =D7/C7 -> 1.3692466 | F7: =D7/8760 -> 0.0006095961 | G7: =1-F7 -> 0.9993904 | H7: =(('DATA AND SCENARIO'!$C$2*R16)+('DATA AND SCENARIO'!$C$3*R17)+('DATA AND SCENARIO'!$C$4*R18)+('DATA AND SCENARIO'!$C$5*R19)+('DATA AND SCENARIO'!$C$6*R20)+('DATA AND SCENARIO'!$C$7*R21)+('DATA AND SCENARIO'!$C$8*R22)+('DATA AND SCENARIO'!$C$9*R23))/SUM('DATA AND SCENARIO'!$B$2:$B$9) -> 2.357518 | I7: =H7*SUM('DATA AND SCENARIO'!$B$2:$B$9) -> 242383.5 | J7: =$I$2-I7 -> 278612.52 | K7: 5 | L7: =J7/K7 -> 55722.505
B8: Case 06 | C8: =('RELIABILITY INDICES'!D104*SUM('DATA AND SCENARIO'!B4:B11))/SUM('DATA AND SCENARIO'!B4:B11) -> 3.9 | D8: =(('DATA AND SCENARIO'!$B$2*U16)+('DATA AND SCENARIO'!$B$3*U17)+('DATA AND SCENARIO'!$B$4*U18)+('DATA AND SCENARIO'!$B$5*U19)+('DATA AND SCENARIO'!$B$6*U20)+('DATA AND SCENARIO'!$B$7*U21)+('DATA AND SCENARIO'!$B$8*U22)+('DATA AND SCENARIO'!$B$9*U23))/SUM('DATA AND SCENARIO'!$B$2:$B$9) -> 5.0239597 | E8: =D8/C8 -> 1.2881948 | F8: =D8/8760 -> 0.00057351138 | G8: =1-F8 -> 0.99942649 | H8: =(('DATA AND SCENARIO'!$C$2*U16)+('DATA AND SCENARIO'!$C$3*U17)+('DATA AND SCENARIO'!$C$4*U18)+('DATA AND SCENARIO'!$C$5*U19)+('DATA AND SCENARIO'!$C$6*U20)+('DATA AND SCENARIO'!$C$7*U21)+('DATA AND SCENARIO'!$C$8*U22)+('DATA AND SCENARIO'!$C$9*U23))/SUM('DATA AND SCENARIO'!$B$2:$B$9) -> 2.251366 | I8: =H8*SUM('DATA AND SCENARIO'!$B$2:$B$9) -> 231469.69 | J8: =$I$2-I8 -> 289526.33 | K8: 6 | L8: =J8/K8 -> 48254.388
B9: Case 07 | C9: =('RELIABILITY INDICES'!D119*SUM('DATA AND SCENARIO'!B5:B12))/SUM('DATA AND SCENARIO'!B5:B12) -> 3.9 | D9: =(('DATA AND SCENARIO'!$B$2*X16)+('DATA AND SCENARIO'!$B$3*X17)+('DATA AND SCENARIO'!$B$4*X18)+('DATA AND SCENARIO'!$B$5*X19)+('DATA AND SCENARIO'!$B$6*X20)+('DATA AND SCENARIO'!$B$7*X21)+('DATA AND SCENARIO'!$B$8*X22)+('DATA AND SCENARIO'!$B$9*X23))/SUM('DATA AND SCENARIO'!$B$2:$B$9) -> 4.9689159 | E9: =D9/C9 -> 1.274081 | F9: =D9/8760 -> 0.00056722784 | G9: =1-F9 -> 0.99943277 | H9: =(('DATA AND SCENARIO'!$C$2*X16)+('DATA AND SCENARIO'!$C$3*X17)+('DATA AND SCENARIO'!$C$4*X18)+('DATA AND SCENARIO'!$C$5*X19)+('DATA AND SCENARIO'!$C$6*X20)+('DATA AND SCENARIO'!$C$7*X21)+('DATA AND SCENARIO'!$C$8*X22)+('DATA AND SCENARIO'!$C$9*X23))/SUM('DATA AND SCENARIO'!$B$2:$B$9) -> 2.2300588 | I9: =H9*SUM('DATA AND SCENARIO'!$B$2:$B$9) -> 229279.03 | J9: =$I$2-I9 -> 291716.99 | K9: 7 | L9: =J9/K9 -> 41673.855
B10: Case 08 | C10: =('RELIABILITY INDICES'!D134*SUM(RESULTS!#REF!))/SUM(RESULTS!#REF!) -> #REF! | D10: =(('DATA AND SCENARIO'!$B$2*AA16)+('DATA AND SCENARIO'!$B$3*AA17)+('DATA AND SCENARIO'!$B$4*AA18)+('DATA AND SCENARIO'!$B$5*AA19)+('DATA AND SCENARIO'!$B$6*AA20)+('DATA AND SCENARIO'!$B$7*AA21)+('DATA AND SCENARIO'!$B$8*AA22)+('DATA AND SCENARIO'!$B$9*AA23))/SUM('DATA AND SCENARIO'!$B$2:$B$9) -> 4.7043777 | E10: =D10/C10 -> #REF! | F10: =D10/8760 -> 0.00053702941 | G10: =1-F10 -> 0.99946297 | H10: =(('DATA AND SCENARIO'!$C$2*AA16)+('DATA AND SCENARIO'!$C$3*AA17)+('DATA AND SCENARIO'!$C$4*AA18)+('DATA AND SCENARIO'!$C$5*AA19)+('DATA AND SCENARIO'!$C$6*AA20)+('DATA AND SCENARIO'!$C$7*AA21)+('DATA AND SCENARIO'!$C$8*AA22)+('DATA AND SCENARIO'!$C$9*AA23))/SUM('DATA AND SCENARIO'!$B$2:$B$9) -> 2.1460134 | I10: =H10*SUM('DATA AND SCENARIO'!$B$2:$B$9) -> 220638.07 | J10: =$I$2-I10 -> 300357.95 | K10: 8 | L10: =J10/K10 -> 37544.743
B15: BASE CASE | C15: U (hours/year) | E15: CASE 1 | F15: U (hours/year) | H15: CASE 2 | I15: U (hours/year) | K15: CASE 3 | L15: U (hours/year) | N15: CASE 4 | O15: U (hours/year) | Q15: CASE 5 | R15: U (hours/year) | T15: CASE 6 | U15: U (hours/year) | W15: CASE 7 | X15: U (hours/year) | Z15: CASE 8 | AA15: U (hours/year)
B16: M1 | C16: ='RELIABILITY INDICES'!F14 -> 10.05 | E16: M1 | F16: ='RELIABILITY INDICES'!$F29 -> 8.7164 | H16: M1 | I16: ='RELIABILITY INDICES'!$F44 -> 8.7164 | K16: M1 | L16: ='RELIABILITY INDICES'!$F59 -> 2.5989 | N16: M1 | O16: ='RELIABILITY INDICES'!$F74 -> 2.5989 | Q16: M1 | R16: ='RELIABILITY INDICES'!$F89 -> 2.5989 | T16: M1 | U16: ='RELIABILITY INDICES'!$F104 -> 2.5989 | W16: M1 | X16: ='RELIABILITY INDICES'!$F119 -> 2.5989 | Z16: M1 | AA16: ='RELIABILITY INDICES'!$F134 -> 2.5989
B17: M2 | C17: ='RELIABILITY INDICES'!I14 -> 10.05 | E17: M2 | F17: ='RELIABILITY INDICES'!$I29 -> 10.05 | H17: M2 | I17: ='RELIABILITY INDICES'!$I44 -> 9.3832 | K17: M2 | L17: ='RELIABILITY INDICES'!$I59 -> 3.2657 | N17: M2 | O17: ='RELIABILITY INDICES'!$I74 -> 3.2657 | Q17: M2 | R17: ='RELIABILITY INDICES'!$I89 -> 3.2657 | T17: M2 | U17: ='RELIABILITY INDICES'!$I104 -> 3.2657 | W17: M2 | X17: ='RELIABILITY INDICES'!$I119 -> 3.2657 | Z17: M2 | AA17: ='RELIABILITY INDICES'!$I134 -> 3.2657
B18: M3 | C18: ='RELIABILITY INDICES'!L14 -> 10.05 | E18: M3 | F18: ='RELIABILITY INDICES'!$L29 -> 10.05 | H18: M3 | I18: ='RELIABILITY INDICES'!$L44 -> 10.05 | K18: M3 | L18: ='RELIABILITY INDICES'!$L59 -> 3.9325 | N18: M3 | O18: ='RELIABILITY INDICES'!$L74 -> 3.9325 | Q18: M3 | R18: ='RELIABILITY INDICES'!$L89 -> 3.9325 | T18: M3 | U18: ='RELIABILITY INDICES'!$L104 -> 3.9325 | W18: M3 | X18: ='RELIABILITY INDICES'!$L119 -> 3.9325 | Z18: M3 | AA18: ='RELIABILITY INDICES'!$L134 -> 3.9325
B19: M4 | C19: ='RELIABILITY INDICES'!O14 -> 10.05 | E19: M4 | F19: ='RELIABILITY INDICES'!$O29 -> 8.7164 | H19: M4 | I19: ='RELIABILITY INDICES'!$O44 -> 8.7164 | K19: M4 | L19: ='RELIABILITY INDICES'!$O59 -> 8.7164 | N19: M4 | O19: ='RELIABILITY INDICES'!$O74 -> 3.699 | Q19: M4 | R19: ='RELIABILITY INDICES'!$O89 -> 3.699 | T19: M4 | U19: ='RELIABILITY INDICES'!$O104 -> 3.699 | W19: M4 | X19: ='RELIABILITY INDICES'!$O119 -> 3.699 | Z19: M4 | AA19: ='RELIABILITY INDICES'!$O134 -> 3.699
B20: M5 | C20: ='RELIABILITY INDICES'!R14 -> 10.05 | E20: M5 | F20: ='RELIABILITY INDICES'!$R29 -> 8.7164 | H20: M5 | I20: ='RELIABILITY INDICES'!$R44 -> 8.7164 | K20: M5 | L20: ='RELIABILITY INDICES'!$R59 -> 8.7164 | N20: M5 | O20: ='RELIABILITY INDICES'!$R74 -> 8.7164 | Q20: M5 | R20: ='RELIABILITY INDICES'!$R89 -> 8.7164 | T20: M5 | U20: ='RELIABILITY INDICES'!$R104 -> 5.7993 | W20: M5 | X20: ='RELIABILITY INDICES'!$R119 -> 5.7993 | Z20: M5 | AA20: ='RELIABILITY INDICES'!$R134 -> 5.7993
B21: M6 | C21: ='RELIABILITY INDICES'!U14 -> 10.05 | E21: M6 | F21: ='RELIABILITY INDICES'!$U29 -> 8.7164 | H21: M6 | I21: ='RELIABILITY INDICES'!$U44 -> 8.7164 | K21: M6 | L21: ='RELIABILITY INDICES'!$U59 -> 8.7164 | N21: M6 | O21: ='RELIABILITY INDICES'!$U74 -> 8.7164 | Q21: M6 | R21: ='RELIABILITY INDICES'!$U89 -> 7.4162 | T21: M6 | U21: ='RELIABILITY INDICES'!$U104 -> 7.4162 | W21: M6 | X21: ='RELIABILITY INDICES'!$U119 -> 6.6327 | Z21: M6 | AA21: ='RELIABILITY INDICES'!$U134 -> 5.8326
B22: M7 | C22: ='RELIABILITY INDICES'!X14 -> 10.05 | E22: M7 | F22: ='RELIABILITY INDICES'!$X29 -> 8.7164 | H22: M7 | I22: ='RELIABILITY INDICES'!$X44 -> 8.7164 | K22: M7 | L22: ='RELIABILITY INDICES'!$X59 -> 8.7164 | N22: M7 | O22: ='RELIABILITY INDICES'!$X74 -> 8.7164 | Q22: M7 | R22: ='RELIABILITY INDICES'!$X89 -> 7.4162 | T22: M7 | U22: ='RELIABILITY INDICES'!$X104 -> 7.4162 | W22: M7 | X22: ='RELIABILITY INDICES'!$X119 -> 7.4162 | Z22: M7 | AA22: ='RELIABILITY INDICES'!$X134 -> 6.7661
B23: M8 | C23: ='RELIABILITY INDICES'!AA14 -> 10.05 | E23: M8 | F23: ='RELIABILITY INDICES'!$AA29 -> 8.7164 | H23: M8 | I23: ='RELIABILITY INDICES'!$AA44 -> 8.7164 | K23: M8 | L23: ='RELIABILITY INDICES'!$AA59 -> 8.7164 | N23: M8 | O23: ='RELIABILITY INDICES'!$AA74 -> 8.7164 | Q23: M8 | R23: ='RELIABILITY INDICES'!$AA89 -> 7.4162 | T23: M8 | U23: ='RELIABILITY INDICES'!$AA104 -> 7.4162 | W23: M8 | X23: ='RELIABILITY INDICES'!$AA119 -> 7.4162 | Z23: M8 | AA23: ='RELIABILITY INDICES'!$AA134 -> 7.4162
